Workbook

Sheet Chart_selective
A1: Ref | C1: "" | D1: Supporting word 1 | E1: Kanji | F1: Supporting word 2 | G1: Meaning
A2: 1 | C2: =VLOOKUP($A2,Final_manabou_kanji_select[[Sr no.]:[Title]],3,0) -> Burmese Favourite | D2: =VLOOKUP($A2,Final_manabou_kanji_select[],MATCH(D$1,Final_manabou_kanji_select[#Headers],0),0) | E2: =VLOOKUP($A2,Final_manabou_kanji_select[],MATCH(E$1,Final_manabou_kanji_select[#Headers],0),0) -> မုန့်ဟင်းခါး | F2: =VLOOKUP($A2,Final_manabou_kanji_select[],MATCH(F$1,Final_manabou_kanji_select[#Headers],0),0) | G2: =IFERROR(VLOOKUP($A2,Final_manabou_kanji_select[],7,0)&", "&VLOOKUP($A2,Final_manabou_kanji_select[],8,0),"")
A3: 2 | C3: =VLOOKUP($A3,Final_manabou_kanji_select[[Sr no.]:[Title]],3,0) -> Burmese Favourite | D3: =VLOOKUP($A3,Final_manabou_kanji_select[],MATCH(D$1,Final_manabou_kanji_select[#Headers],0),0) | E3: =VLOOKUP($A3,Final_manabou_kanji_select[],MATCH(E$1,Final_manabou_kanji_select[#Headers],0),0) -> ဘူးသီးကြော် | F3: =VLOOKUP($A3,Final_manabou_kanji_select[],MATCH(F$1,Final_manabou_kanji_select[#Headers],0),0) | G3: =IFERROR(VLOOKUP($A3,Final_manabou_kanji_select[],7,0)&", "&VLOOKUP($A3,Final_manabou_kanji_select[],8,0),"")
A4: 3 | C4: =VLOOKUP($A4,Final_manabou_kanji_select[[Sr no.]:[Title]],3,0) -> Burmese Favourite | D4: =VLOOKUP($A4,Final_manabou_kanji_select[],MATCH(D$1,Final_manabou_kanji_select[#Headers],0),0) | E4: =VLOOKUP($A4,Final_manabou_kanji_select[],MATCH(E$1,Final_manabou_kanji_select[#Headers],0),0) -> ပဲကက်ကြော် | F4: =VLOOKUP($A4,Final_manabou_kanji_select[],MATCH(F$1,Final_manabou_kanji_select[#Headers],0),0) | G4: =IFERROR(VLOOKUP($A4,Final_manabou_kanji_select[],7,0)&", "&VLOOKUP($A4,Final_manabou_kanji_select[],8,0),"")
A5: 4 | C5: =VLOOKUP($A5,Final_manabou_kanji_select[[Sr no.]:[Title]],3,0) -> Burmese Favourite | D5: =VLOOKUP($A5,Final_manabou_kanji_select[],MATCH(D$1,Final_manabou_kanji_select[#Headers],0),0) | E5: =VLOOKUP($A5,Final_manabou_kanji_select[],MATCH(E$1,Final_manabou_kanji_select[#Headers],0),0) -> ပုစွန်ကက်ကြော် | F5: =VLOOKUP($A5,Final_manabou_kanji_select[],MATCH(F$1,Final_manabou_kanji_select[#Headers],0),0) | G5: =IFERROR(VLOOKUP($A5,Final_manabou_kanji_select[],7,0)&", "&VLOOKUP($A5,Final_manabou_kanji_select[],8,0),"")
A6: 5 | C6: =VLOOKUP($A6,Final_manabou_kanji_select[[Sr no.]:[Title]],3,0) -> Burmese Favourite | D6: =VLOOKUP($A6,Final_manabou_kanji_select[],MATCH(D$1,Final_manabou_kanji_select[#Headers],0),0) | E6: =VLOOKUP($A6,Final_manabou_kanji_select[],MATCH(E$1,Final_manabou_kanji_select[#Headers],0),0) -> ကြက်သွန်ကြော် | F6: =VLOOKUP($A6,Final_manabou_kanji_select[],MATCH(F$1,Final_manabou_kanji_select[#Headers],0),0) | G6: =IFERROR(VLOOKUP($A6,Final_manabou_kanji_select[],7,0)&", "&VLOOKUP($A6,Final_manabou_kanji_select[],8,0),"")
A7: 6 | C7: =VLOOKUP($A7,Final_manabou_kanji_select[[Sr no.]:[Title]],3,0) -> Burmese Favourite | D7: =VLOOKUP($A7,Final_manabou_kanji_select[],MATCH(D$1,Final_manabou_kanji_select[#Headers],0),0) | E7: =VLOOKUP($A7,Final_manabou_kanji_select[],MATCH(E$1,Final_manabou_kanji_select[#Headers],0),0) -> ငါးဖယ်ကြော် | F7: =VLOOKUP($A7,Final_manabou_kanji_select[],MATCH(F$1,Final_manabou_kanji_select[#Headers],0),0) | G7: =IFERROR(VLOOKUP($A7,Final_manabou_kanji_select[],7,0)&", "&VLOOKUP($A7,Final_manabou_kanji_select[],8,0),"")
A8: 7 | C8: =VLOOKUP($A8,Final_manabou_kanji_select[[Sr no.]:[Title]],3,0) -> Burmese Favourite | D8: =VLOOKUP($A8,Final_manabou_kanji_select[],MATCH(D$1,Final_manabou_kanji_select[#Headers],0),0) | E8: =VLOOKUP($A8,Final_manabou_kanji_select[],MATCH(E$1,Final_manabou_kanji_select[#Headers],0),0) -> ဘဲဥပြုတ် | F8: =VLOOKUP($A8,Final_manabou_kanji_select[],MATCH(F$1,Final_manabou_kanji_select[#Headers],0),0) | G8: =IFERROR(VLOOKUP($A8,Final_manabou_kanji_select[],7,0)&", "&VLOOKUP($A8,Final_manabou_kanji_select[],8,0),"") -> , Boiled Duck Egg
A9: 8 | C9: =VLOOKUP($A9,Final_manabou_kanji_select[[Sr no.]:[Title]],3,0) -> Burmese Favourite | D9: =VLOOKUP($A9,Final_manabou_kanji_select[],MATCH(D$1,Final_manabou_kanji_select[#Headers],0),0) | E9: =VLOOKUP($A9,Final_manabou_kanji_select[],MATCH(E$1,Final_manabou_kanji_select[#Headers],0),0) -> နံနံပင် | F9: =VLOOKUP($A9,Final_manabou_kanji_select[],MATCH(F$1,Final_manabou_kanji_select[#Headers],0),0) | G9: =IFERROR(VLOOKUP($A9,Final_manabou_kanji_select[],7,0)&", "&VLOOKUP($A9,Final_manabou_kanji_select[],8,0),"")
A10: 9 | C10: =VLOOKUP($A10,Final_manabou_kanji_select[[Sr no.]:[Title]],3,0) -> Burmese Favourite | D10: =VLOOKUP($A10,Final_manabou_kanji_select[],MATCH(D$1,Final_manabou_kanji_select[#Headers],0),0) | E10: =VLOOKUP($A10,Final_manabou_kanji_select[],MATCH(E$1,Final_manabou_kanji_select[#Headers],0),0) -> ငရုတ်သီးမှုန့် | F10: =VLOOKUP($A10,Final_manabou_kanji_select[],MATCH(F$1,Final_manabou_kanji_select[#Headers],0),0) | G10: =IFERROR(VLOOKUP($A10,Final_manabou_kanji_select[],7,0)&", "&VLOOKUP($A10,Final_manabou_kanji_select[],8,0),"")
A11: 10 | C11: =VLOOKUP($A11,Final_manabou_kanji_select[[Sr no.]:[Title]],3,0) -> Burmese Favourite | D11: =VLOOKUP($A11,Final_manabou_kanji_select[],MATCH(D$1,Final_manabou_kanji_select[#Headers],0),0) | E11: =VLOOKUP($A11,Final_manabou_kanji_select[],MATCH(E$1,Final_manabou_kanji_select[#Headers],0),0) -> ကြက်သွန်နီ | F11: =VLOOKUP($A11,Final_manabou_kanji_select[],MATCH(F$1,Final_manabou_kanji_select[#Headers],0),0) | G11: =IFERROR(VLOOKUP($A11,Final_manabou_kanji_select[],7,0)&", "&VLOOKUP($A11,Final_manabou_kanji_select[],8,0),"")
A12: 11 | C12: =VLOOKUP($A12,Final_manabou_kanji_select[[Sr no.]:[Title]],3,0) -> Burmese Favourite | D12: =VLOOKUP($A12,Final_manabou_kanji_select[],MATCH(D$1,Final_manabou_kanji_select[#Headers],0),0) | E12: =VLOOKUP($A12,Final_manabou_kanji_select[],MATCH(E$1,Final_manabou_kanji_select[#Headers],0),0) -> သံပရာသီး | F12: =VLOOKUP($A12,Final_manabou_kanji_select[],MATCH(F$1,Final_manabou_kanji_select[#Headers],0),0) | G12: =IFERROR(VLOOKUP($A12,Final_manabou_kanji_select[],7,0)&", "&VLOOKUP($A12,Final_manabou_kanji_select[],8,0),"")
A13: 12 | C13: =VLOOKUP($A13,Final_manabou_kanji_select[[Sr no.]:[Title]],3,0) -> Burmese Favourite | D13: =VLOOKUP($A13,Final_manabou_kanji_select[],MATCH(D$1,Final_manabou_kanji_select[#Headers],0),0) | E13: =VLOOKUP($A13,Final_manabou_kanji_select[],MATCH(E$1,Final_manabou_kanji_select[#Headers],0),0) -> ဆီချက် | F13: =VLOOKUP($A13,Final_manabou_kanji_select[],MATCH(F$1,Final_manabou_kanji_select[#Headers],0),0) | G13: =IFERROR(VLOOKUP($A13,Final_manabou_kanji_select[],7,0)&", "&VLOOKUP($A13,Final_manabou_kanji_select[],8,0),"")
... A802: 801 | C802: =VLOOKUP($A802,Final_manabou_kanji_select[[Sr no.]:[Title]],3,0) -> #N/A | D802: =VLOOKUP($A802,Final_manabou_kanji_select[],MATCH(D$1,Final_manabou_kanji_select[#Headers],0),0) -> #N/A | E802: =VLOOKUP($A802,Final_manabou_kanji_select[],MATCH(E$1,Final_manabou_kanji_select[#Headers],0),0) -> #N/A | F802: =VLOOKUP($A802,Final_manabou_kanji_select[],MATCH(F$1,Final_manabou_kanji_select[#Headers],0),0) -> #N/A | G802: =IFERROR(VLOOKUP($A802,Final_manabou_kanji_select[],7,0)&", "&VLOOKUP($A802,Final_manabou_kanji_select[],8,0),"")

Sheet Chart
C1: 1 | D1: 2 | E1: 3 | F1: 4 | G1: 5 | H1: 6 | I1: 7 | J1: 8 | L1: Column1 | M1: 1 | N1: 2 | O1: 3 | P1: 4 | Q1: 5 | R1: 6 | S1: 7 | T1: 8 | X1: 1 | Y1: 2 | Z1: 3 | AA1: 4 | AB1: 5 | AC1: 6 | AD1: 7 | AE1: 8 | AI1: 1 | AJ1: 2 | AK1: 3 | AL1: 4 | AM1: 5 | AN1: 6 | AO1: 7 | AP1: 8
A2: =IF($X2=1,$A1+1,$A1) -> 1 | B2: =IF(V2="",$B1,$V2) -> 1章1課 | C2: =IFERROR(VLOOKUP($B2&"_"&X2,Raw_data_N2_Kanji[[Receipe no]:[Receipe]],4,0),"") | D2: =IFERROR(VLOOKUP($B2&"_"&Y2,Raw_data_N2_Kanji[[Receipe no]:[Receipe]],4,0),"") | E2: =IFERROR(VLOOKUP($B2&"_"&Z2,Raw_data_N2_Kanji[[Receipe no]:[Receipe]],4,0),"") | F2: =IFERROR(VLOOKUP($B2&"_"&AA2,Raw_data_N2_Kanji[[Receipe no]:[Receipe]],4,0),"") | G2: =IFERROR(VLOOKUP($B2&"_"&AB2,Raw_data_N2_Kanji[[Receipe no]:[Receipe]],4,0),"") | H2: =IFERROR(VLOOKUP($B2&"_"&AC2,Raw_data_N2_Kanji[[Receipe no]:[Receipe]],4,0),"") | I2: =IFERROR(VLOOKUP($B2&"_"&AD2,Raw_data_N2_Kanji[[Receipe no]:[Receipe]],4,0),"") | J2: =IFERROR(VLOOKUP($B2&"_"&AE2,Raw_data_N2_Kanji[[Receipe no]:[Receipe]],4,0),"") | L2: =$W2 -> 1章1課 | M2: =IFERROR(VLOOKUP($L2&"_"&X2,Final_manabou_kanji[],6,0),"") | N2: =IFERROR(VLOOKUP($L2&"_"&Y2,Final_manabou_kanji[],6,0),"") | O2: =IFERROR(VLOOKUP($L2&"_"&Z2,Final_manabou_kanji[],6,0),"") | P2: =IFERROR(VLOOKUP($L2&"_"&AA2,Final_manabou_kanji[],6,0),"") | Q2: =IFERROR(VLOOKUP($L2&"_"&AB2,Final_manabou_kanji[],6,0),"") | R2: =IFERROR(VLOOKUP($L2&"_"&AC2,Final_manabou_kanji[],6,0),"") | S2: =IFERROR(VLOOKUP($L2&"_"&AD2,Final_manabou_kanji[],6,0),"") | T2: =IFERROR(VLOOKUP($L2&"_"&AE2,Final_manabou_kanji[],6,0),"") | V2: 1章1課 | W2: =IF(V2="",$W1,$V2) -> 1章1課 | X2: =IF($V2="",X1+8,X$1) -> 1 | Y2: =IF($V2="",Y1+8,Y$1) -> 2 | Z2: =IF($V2="",Z1+8,Z$1) -> 3 | AA2: =IF($V2="",AA1+8,AA$1) -> 4 | AB2: =IF($V2="",AB1+8,AB$1) -> 5 | AC2: =IF($V2="",AC1+8,AC$1) -> 6 | AD2: =IF($V2="",AD1+8,AD$1) -> 7 | AE2: =IF($V2="",AE1+8,AE$1) -> 8 | AH2: 21 | AI2: =$W2&X2 -> 1章1課1 | AJ2: =$W2&Y2 -> 1章1課2 | AK2: =$W2&Z2 -> 1章1課3 | AL2: =$W2&AA2 -> 1章1課4 | AM2: =$W2&AB2 -> 1章1課5 | AN2: =$W2&AC2 -> 1章1課6 | AO2: =$W2&AD2 -> 1章1課7 | AP2: =$W2&AE2 -> 1章1課8
A3: =IF($X3=1,$A2+1,$A2) -> 1 | B3: =IF(V3="",$B2,$V3) -> 1章1課 | C3: =IFERROR(VLOOKUP($B3&"_"&X3,Raw_data_N2_Kanji[[Receipe no]:[Receipe]],4,0),"") | D3: =IFERROR(VLOOKUP($B3&"_"&Y3,Raw_data_N2_Kanji[[Receipe no]:[Receipe]],4,0),"") | E3: =IFERROR(VLOOKUP($B3&"_"&Z3,Raw_data_N2_Kanji[[Receipe no]:[Receipe]],4,0),"") | F3: =IFERROR(VLOOKUP($B3&"_"&AA3,Raw_data_N2_Kanji[[Receipe no]:[Receipe]],4,0),"") | G3: =IFERROR(VLOOKUP($B3&"_"&AB3,Raw_data_N2_Kanji[[Receipe no]:[Receipe]],4,0),"") | H3: =IFERROR(VLOOKUP($B3&"_"&AC3,Raw_data_N2_Kanji[[Receipe no]:[Receipe]],4,0),"") | I3: =IFERROR(VLOOKUP($B3&"_"&AD3,Raw_data_N2_Kanji[[Receipe no]:[Receipe]],4,0),"") | J3: =IFERROR(VLOOKUP($B3&"_"&AE3,Raw_data_N2_Kanji[[Receipe no]:[Receipe]],4,0),"") | L3: =$W3 -> 1章1課 | M3: =IFERROR(VLOOKUP($L3&"_"&X3,Final_manabou_kanji[],6,0),"") | N3: =IFERROR(VLOOKUP($L3&"_"&Y3,Final_manabou_kanji[],6,0),"") | O3: =IFERROR(VLOOKUP($L3&"_"&Z3,Final_manabou_kanji[],6,0),"") | P3: =IFERROR(VLOOKUP($L3&"_"&AA3,Final_manabou_kanji[],6,0),"") | Q3: =IFERROR(VLOOKUP($L3&"_"&AB3,Final_manabou_kanji[],6,0),"") | R3: =IFERROR(VLOOKUP($L3&"_"&AC3,Final_manabou_kanji[],6,0),"") | S3: =IFERROR(VLOOKUP($L3&"_"&AD3,Final_manabou_kanji[],6,0),"") | T3: =IFERROR(VLOOKUP($L3&"_"&AE3,Final_manabou_kanji[],6,0),"") | W3: =IF(V3="",$W2,$V3) -> 1章1課 | X3: =IF($V3="",X2+8,X$1) -> 9 | Y3: =IF($V3="",Y2+8,Y$1) -> 10 | Z3: =IF($V3="",Z2+8,Z$1) -> 11 | AA3: =IF($V3="",AA2+8,AA$1) -> 12 | AB3: =IF($V3="",AB2+8,AB$1) -> 13 | AC3: =IF($V3="",AC2+8,AC$1) -> 14 | AD3: =IF($V3="",AD2+8,AD$1) -> 15 | AE3: =IF($V3="",AE2+8,AE$1) -> 16 | AH3: 21 | AI3: =$W3&X3 -> 1章1課9 | AJ3: =$W3&Y3 -> 1章1課10 | AK3: =$W3&Z3 -> 1章1課11 | AL3: =$W3&AA3 -> 1章1課12 | AM3: =$W3&AB3 -> 1章1課13 | AN3: =$W3&AC3 -> 1章1課14 | AO3: =$W3&AD3 -> 1章1課15 | AP3: =$W3&AE3 -> 1章1課16
A4: =IF($X4=1,$A3+1,$A3) -> 1 | B4: =IF(V4="",$B3,$V4) -> 1章1課 | C4: =IFERROR(VLOOKUP($B4&"_"&X4,Raw_data_N2_Kanji[[Receipe no]:[Receipe]],4,0),"") | D4: =IFERROR(VLOOKUP($B4&"_"&Y4,Raw_data_N2_Kanji[[Receipe no]:[Receipe]],4,0),"") | E4: =IFERROR(VLOOKUP($B4&"_"&Z4,Raw_data_N2_Kanji[[Receipe no]:[Receipe]],4,0),"") | F4: =IFERROR(VLOOKUP($B4&"_"&AA4,Raw_data_N2_Kanji[[Receipe no]:[Receipe]],4,0),"") | G4: =IFERROR(VLOOKUP($B4&"_"&AB4,Raw_data_N2_Kanji[[Receipe no]:[Receipe]],4,0),"") | H4: =IFERROR(VLOOKUP($B4&"_"&AC4,Raw_data_N2_Kanji[[Receipe no]:[Receipe]],4,0),"") | I4: =IFERROR(VLOOKUP($B4&"_"&AD4,Raw_data_N2_Kanji[[Receipe no]:[Receipe]],4,0),"") | J4: =IFERROR(VLOOKUP($B4&"_"&AE4,Raw_data_N2_Kanji[[Receipe no]:[Receipe]],4,0),"") | L4: =$W4 -> 1章1課 | M4: =IFERROR(VLOOKUP($L4&"_"&X4,Final_manabou_kanji[],6,0),"") | N4: =IFERROR(VLOOKUP($L4&"_"&Y4,Final_manabou_kanji[],6,0),"") | O4: =IFERROR(VLOOKUP($L4&"_"&Z4,Final_manabou_kanji[],6,0),"") | P4: =IFERROR(VLOOKUP($L4&"_"&AA4,Final_manabou_kanji[],6,0),"") | Q4: =IFERROR(VLOOKUP($L4&"_"&AB4,Final_manabou_kanji[],6,0),"") | R4: =IFERROR(VLOOKUP($L4&"_"&AC4,Final_manabou_kanji[],6,0),"") | S4: =IFERROR(VLOOKUP($L4&"_"&AD4,Final_manabou_kanji[],6,0),"") | T4: =IFERROR(VLOOKUP($L4&"_"&AE4,Final_manabou_kanji[],6,0),"") | W4: =IF(V4="",$W3,$V4) -> 1章1課 | X4: =IF($V4="",X3+8,X$1) -> 17 | Y4: =IF($V4="",Y3+8,Y$1) -> 18 | Z4: =IF($V4="",Z3+8,Z$1) -> 19 | AA4: =IF($V4="",AA3+8,AA$1) -> 20 | AB4: =IF($V4="",AB3+8,AB$1) -> 21 | AC4: =IF($V4="",AC3+8,AC$1) -> 22 | AD4: =IF($V4="",AD3+8,AD$1) -> 23 | AE4: =IF($V4="",AE3+8,AE$1) -> 24 | AH4: 21 | AI4: =$W4&X4 -> 1章1課17 | AJ4: =$W4&Y4 -> 1章1課18 | AK4: =$W4&Z4 -> 1章1課19 | AL4: =$W4&AA4 -> 1章1課20 | AM4: =$W4&AB4 -> 1章1課21 | AN4: =$W4&AC4 -> 1章1課22 | AO4: =$W4&AD4 -> 1章1課23 | AP4: =$W4&AE4 -> 1章1課24
A5: =IF($X5=1,$A4+1,$A4) -> 1 | B5: =IF(V5="",$B4,$V5) -> 1章1課 | C5: =IFERROR(VLOOKUP($B5&"_"&X5,Raw_data_N2_Kanji[[Receipe no]:[Receipe]],4,0),"") | D5: =IFERROR(VLOOKUP($B5&"_"&Y5,Raw_data_N2_Kanji[[Receipe no]:[Receipe]],4,0),"") | E5: =IFERROR(VLOOKUP($B5&"_"&Z5,Raw_data_N2_Kanji[[Receipe no]:[Receipe]],4,0),"") | F5: =IFERROR(VLOOKUP($B5&"_"&AA5,Raw_data_N2_Kanji[[Receipe no]:[Receipe]],4,0),"") | G5: =IFERROR(VLOOKUP($B5&"_"&AB5,Raw_data_N2_Kanji[[Receipe no]:[Receipe]],4,0),"") | H5: =IFERROR(VLOOKUP($B5&"_"&AC5,Raw_data_N2_Kanji[[Receipe no]:[Receipe]],4,0),"") | I5: =IFERROR(VLOOKUP($B5&"_"&AD5,Raw_data_N2_Kanji[[Receipe no]:[Receipe]],4,0),"") | J5: =IFERROR(VLOOKUP($B5&"_"&AE5,Raw_data_N2_Kanji[[Receipe no]:[Receipe]],4,0),"") | L5: =$W5 -> 1章1課 | M5: =IFERROR(VLOOKUP($L5&"_"&X5,Final_manabou_kanji[],6,0),"") | N5: =IFERROR(VLOOKUP($L5&"_"&Y5,Final_manabou_kanji[],6,0),"") | O5: =IFERROR(VLOOKUP($L5&"_"&Z5,Final_manabou_kanji[],6,0),"") | P5: =IFERROR(VLOOKUP($L5&"_"&AA5,Final_manabou_kanji[],6,0),"") | Q5: =IFERROR(VLOOKUP($L5&"_"&AB5,Final_manabou_kanji[],6,0),"") | R5: =IFERROR(VLOOKUP($L5&"_"&AC5,Final_manabou_kanji[],6,0),"") | S5: =IFERROR(VLOOKUP($L5&"_"&AD5,Final_manabou_kanji[],6,0),"") | T5: =IFERROR(VLOOKUP($L5&"_"&AE5,Final_manabou_kanji[],6,0),"") | W5: =IF(V5="",$W4,$V5) -> 1章1課 | X5: =IF($V5="",X4+8,X$1) -> 25 | Y5: =IF($V5="",Y4+8,Y$1) -> 26 | Z5: =IF($V5="",Z4+8,Z$1) -> 27 | AA5: =IF($V5="",AA4+8,AA$1) -> 28 | AB5: =IF($V5="",AB4+8,AB$1) -> 29 | AC5: =IF($V5="",AC4+8,AC$1) -> 30 | AD5: =IF($V5="",AD4+8,AD$1) -> 31 | AE5: =IF($V5="",AE4+8,AE$1) -> 32 | AH5: 21 | AI5: =$W5&X5 -> 1章1課25 | AJ5: =$W5&Y5 -> 1章1課26 | AK5: =$W5&Z5 -> 1章1課27 | AL5: =$W5&AA5 -> 1章1課28 | AM5: =$W5&AB5 -> 1章1課29 | AN5: =$W5&AC5 -> 1章1課30 | AO5: =$W5&AD5 -> 1章1課31 | AP5: =$W5&AE5 -> 1章1課32
A6: =IF($X6=1,$A5+1,$A5) -> 2 | B6: =IF(V6="",$B5,$V6) -> 1章2課 | C6: =IFERROR(VLOOKUP($B6&"_"&X6,Raw_data_N2_Kanji[[Receipe no]:[Receipe]],4,0),"") | D6: =IFERROR(VLOOKUP($B6&"_"&Y6,Raw_data_N2_Kanji[[Receipe no]:[Receipe]],4,0),"") | E6: =IFERROR(VLOOKUP($B6&"_"&Z6,Raw_data_N2_Kanji[[Receipe no]:[Receipe]],4,0),"") | F6: =IFERROR(VLOOKUP($B6&"_"&AA6,Raw_data_N2_Kanji[[Receipe no]:[Receipe]],4,0),"") | G6: =IFERROR(VLOOKUP($B6&"_"&AB6,Raw_data_N2_Kanji[[Receipe no]:[Receipe]],4,0),"") | H6: =IFERROR(VLOOKUP($B6&"_"&AC6,Raw_data_N2_Kanji[[Receipe no]:[Receipe]],4,0),"") | I6: =IFERROR(VLOOKUP($B6&"_"&AD6,Raw_data_N2_Kanji[[Receipe no]:[Receipe]],4,0),"") | J6: =IFERROR(VLOOKUP($B6&"_"&AE6,Raw_data_N2_Kanji[[Receipe no]:[Receipe]],4,0),"") | L6: =$W6 -> 1章2課 | M6: =IFERROR(VLOOKUP($L6&"_"&X6,Final_manabou_kanji[],6,0),"") | N6: =IFERROR(VLOOKUP($L6&"_"&Y6,Final_manabou_kanji[],6,0),"") | O6: =IFERROR(VLOOKUP($L6&"_"&Z6,Final_manabou_kanji[],6,0),"") | P6: =IFERROR(VLOOKUP($L6&"_"&AA6,Final_manabou_kanji[],6,0),"") | Q6: =IFERROR(VLOOKUP($L6&"_"&AB6,Final_manabou_kanji[],6,0),"") | R6: =IFERROR(VLOOKUP($L6&"_"&AC6,Final_manabou_kanji[],6,0),"") | S6: =IFERROR(VLOOKUP($L6&"_"&AD6,Final_manabou_kanji[],6,0),"") | T6: =IFERROR(VLOOKUP($L6&"_"&AE6,Final_manabou_kanji[],6,0),"") | V6: 1章2課 | W6: =IF(V6="",$W5,$V6) -> 1章2課 | X6: =IF($V6="",X5+8,X$1) -> 1 | Y6: =IF($V6="",Y5+8,Y$1) -> 2 | Z6: =IF($V6="",Z5+8,Z$1) -> 3 | AA6: =IF($V6="",AA5+8,AA$1) -> 4 | AB6: =IF($V6="",AB5+8,AB$1) -> 5 | AC6: =IF($V6="",AC5+8,AC$1) -> 6 | AD6: =IF($V6="",AD5+8,AD$1) -> 7 | AE6: =IF($V6="",AE5+8,AE$1) -> 8 | AH6: 21 | AI6: =$W6&X6 -> 1章2課1 | AJ6: =$W6&Y6 -> 1章2課2 | AK6: =$W6&Z6 -> 1章2課3 | AL6: =$W6&AA6 -> 1章2課4 | AM6: =$W6&AB6 -> 1章2課5 | AN6: =$W6&AC6 -> 1章2課6 | AO6: =$W6&AD6 -> 1章2課7 | AP6: =$W6&AE6 -> 1章2課8
A7: =IF($X7=1,$A6+1,$A6) -> 2 | B7: =IF(V7="",$B6,$V7) -> 1章2課 | C7: =IFERROR(VLOOKUP($B7&"_"&X7,Raw_data_N2_Kanji[[Receipe no]:[Receipe]],4,0),"") | D7: =IFERROR(VLOOKUP($B7&"_"&Y7,Raw_data_N2_Kanji[[Receipe no]:[Receipe]],4,0),"") | E7: =IFERROR(VLOOKUP($B7&"_"&Z7,Raw_data_N2_Kanji[[Receipe no]:[Receipe]],4,0),"") | F7: =IFERROR(VLOOKUP($B7&"_"&AA7,Raw_data_N2_Kanji[[Receipe no]:[Receipe]],4,0),"") | G7: =IFERROR(VLOOKUP($B7&"_"&AB7,Raw_data_N2_Kanji[[Receipe no]:[Receipe]],4,0),"") | H7: =IFERROR(VLOOKUP($B7&"_"&AC7,Raw_data_N2_Kanji[[Receipe no]:[Receipe]],4,0),"") | I7: =IFERROR(VLOOKUP($B7&"_"&AD7,Raw_data_N2_Kanji[[Receipe no]:[Receipe]],4,0),"") | J7: =IFERROR(VLOOKUP($B7&"_"&AE7,Raw_data_N2_Kanji[[Receipe no]:[Receipe]],4,0),"") | L7: =$W7 -> 1章2課 | M7: =IFERROR(VLOOKUP($L7&"_"&X7,Final_manabou_kanji[],6,0),"") | N7: =IFERROR(VLOOKUP($L7&"_"&Y7,Final_manabou_kanji[],6,0),"") | O7: =IFERROR(VLOOKUP($L7&"_"&Z7,Final_manabou_kanji[],6,0),"") | P7: =IFERROR(VLOOKUP($L7&"_"&AA7,Final_manabou_kanji[],6,0),"") | Q7: =IFERROR(VLOOKUP($L7&"_"&AB7,Final_manabou_kanji[],6,0),"") | R7: =IFERROR(VLOOKUP($L7&"_"&AC7,Final_manabou_kanji[],6,0),"") | S7: =IFERROR(VLOOKUP($L7&"_"&AD7,Final_manabou_kanji[],6,0),"") | T7: =IFERROR(VLOOKUP($L7&"_"&AE7,Final_manabou_kanji[],6,0),"") | W7: =IF(V7="",$W6,$V7) -> 1章2課 | X7: =IF($V7="",X6+8,X$1) -> 9 | Y7: =IF($V7="",Y6+8,Y$1) -> 10 | Z7: =IF($V7="",Z6+8,Z$1) -> 11 | AA7: =IF($V7="",AA6+8,AA$1) -> 12 | AB7: =IF($V7="",AB6+8,AB$1) -> 13 | AC7: =IF($V7="",AC6+8,AC$1) -> 14 | AD7: =IF($V7="",AD6+8,AD$1) -> 15 | AE7: =IF($V7="",AE6+8,AE$1) -> 16 | AH7: 21 | AI7: =$W7&X7 -> 1章2課9 | AJ7: =$W7&Y7 -> 1章2課10 | AK7: =$W7&Z7 -> 1章2課11 | AL7: =$W7&AA7 -> 1章2課12 | AM7: =$W7&AB7 -> 1章2課13 | AN7: =$W7&AC7 -> 1章2課14 | AO7: =$W7&AD7 -> 1章2課15 | AP7: =$W7&AE7 -> 1章2課16
A8: =IF($X8=1,$A7+1,$A7) -> 2 | B8: =IF(V8="",$B7,$V8) -> 1章2課 | C8: =IFERROR(VLOOKUP($B8&"_"&X8,Raw_data_N2_Kanji[[Receipe no]:[Receipe]],4,0),"") | D8: =IFERROR(VLOOKUP($B8&"_"&Y8,Raw_data_N2_Kanji[[Receipe no]:[Receipe]],4,0),"") | E8: =IFERROR(VLOOKUP($B8&"_"&Z8,Raw_data_N2_Kanji[[Receipe no]:[Receipe]],4,0),"") | F8: =IFERROR(VLOOKUP($B8&"_"&AA8,Raw_data_N2_Kanji[[Receipe no]:[Receipe]],4,0),"") | G8: =IFERROR(VLOOKUP($B8&"_"&AB8,Raw_data_N2_Kanji[[Receipe no]:[Receipe]],4,0),"") | H8: =IFERROR(VLOOKUP($B8&"_"&AC8,Raw_data_N2_Kanji[[Receipe no]:[Receipe]],4,0),"") | I8: =IFERROR(VLOOKUP($B8&"_"&AD8,Raw_data_N2_Kanji[[Receipe no]:[Receipe]],4,0),"") | J8: =IFERROR(VLOOKUP($B8&"_"&AE8,Raw_data_N2_Kanji[[Receipe no]:[Receipe]],4,0),"") | L8: =$W8 -> 1章2課 | M8: =IFERROR(VLOOKUP($L8&"_"&X8,Final_manabou_kanji[],6,0),"") | N8: =IFERROR(VLOOKUP($L8&"_"&Y8,Final_manabou_kanji[],6,0),"") | O8: =IFERROR(VLOOKUP($L8&"_"&Z8,Final_manabou_kanji[],6,0),"") | P8: =IFERROR(VLOOKUP($L8&"_"&AA8,Final_manabou_kanji[],6,0),"") | Q8: =IFERROR(VLOOKUP($L8&"_"&AB8,Final_manabou_kanji[],6,0),"") | R8: =IFERROR(VLOOKUP($L8&"_"&AC8,Final_manabou_kanji[],6,0),"") | S8: =IFERROR(VLOOKUP($L8&"_"&AD8,Final_manabou_kanji[],6,0),"") | T8: =IFERROR(VLOOKUP($L8&"_"&AE8,Final_manabou_kanji[],6,0),"") | W8: =IF(V8="",$W7,$V8) -> 1章2課 | X8: =IF($V8="",X7+8,X$1) -> 17 | Y8: =IF($V8="",Y7+8,Y$1) -> 18 | Z8: =IF($V8="",Z7+8,Z$1) -> 19 | AA8: =IF($V8="",AA7+8,AA$1) -> 20 | AB8: =IF($V8="",AB7+8,AB$1) -> 21 | AC8: =IF($V8="",AC7+8,AC$1) -> 22 | AD8: =IF($V8="",AD7+8,AD$1) -> 23 | AE8: =IF($V8="",AE7+8,AE$1) -> 24 | AH8: 21 | AI8: =$W8&X8 -> 1章2課17 | AJ8: =$W8&Y8 -> 1章2課18 | AK8: =$W8&Z8 -> 1章2課19 | AL8: =$W8&AA8 -> 1章2課20 | AM8: =$W8&AB8 -> 1章2課21 | AN8: =$W8&AC8 -> 1章2課22 | AO8: =$W8&AD8 -> 1章2課23 | AP8: =$W8&AE8 -> 1章2課24
A9: =IF($X9=1,$A8+1,$A8) -> 2 | B9: =IF(V9="",$B8,$V9) -> 1章2課 | C9: =IFERROR(VLOOKUP($B9&"_"&X9,Raw_data_N2_Kanji[[Receipe no]:[Receipe]],4,0),"") | D9: =IFERROR(VLOOKUP($B9&"_"&Y9,Raw_data_N2_Kanji[[Receipe no]:[Receipe]],4,0),"") | E9: =IFERROR(VLOOKUP($B9&"_"&Z9,Raw_data_N2_Kanji[[Receipe no]:[Receipe]],4,0),"") | F9: =IFERROR(VLOOKUP($B9&"_"&AA9,Raw_data_N2_Kanji[[Receipe no]:[Receipe]],4,0),"") | G9: =IFERROR(VLOOKUP($B9&"_"&AB9,Raw_data_N2_Kanji[[Receipe no]:[Receipe]],4,0),"") | H9: =IFERROR(VLOOKUP($B9&"_"&AC9,Raw_data_N2_Kanji[[Receipe no]:[Receipe]],4,0),"") | I9: =IFERROR(VLOOKUP($B9&"_"&AD9,Raw_data_N2_Kanji[[Receipe no]:[Receipe]],4,0),"") | J9: =IFERROR(VLOOKUP($B9&"_"&AE9,Raw_data_N2_Kanji[[Receipe no]:[Receipe]],4,0),"") | L9: =$W9 -> 1章2課 | M9: =IFERROR(VLOOKUP($L9&"_"&X9,Final_manabou_kanji[],6,0),"") | N9: =IFERROR(VLOOKUP($L9&"_"&Y9,Final_manabou_kanji[],6,0),"") | O9: =IFERROR(VLOOKUP($L9&"_"&Z9,Final_manabou_kanji[],6,0),"") | P9: =IFERROR(VLOOKUP($L9&"_"&AA9,Final_manabou_kanji[],6,0),"") | Q9: =IFERROR(VLOOKUP($L9&"_"&AB9,Final_manabou_kanji[],6,0),"") | R9: =IFERROR(VLOOKUP($L9&"_"&AC9,Final_manabou_kanji[],6,0),"") | S9: =IFERROR(VLOOKUP($L9&"_"&AD9,Final_manabou_kanji[],6,0),"") | T9: =IFERROR(VLOOKUP($L9&"_"&AE9,Final_manabou_kanji[],6,0),"") | W9: =IF(V9="",$W8,$V9) -> 1章2課 | X9: =IF($V9="",X8+8,X$1) -> 25 | Y9: =IF($V9="",Y8+8,Y$1) -> 26 | Z9: =IF($V9="",Z8+8,Z$1) -> 27 | AA9: =IF($V9="",AA8+8,AA$1) -> 28 | AB9: =IF($V9="",AB8+8,AB$1) -> 29 | AC9: =IF($V9="",AC8+8,AC$1) -> 30 | AD9: =IF($V9="",AD8+8,AD$1) -> 31 | AE9: =IF($V9="",AE8+8,AE$1) -> 32 | AH9: 21 | AI9: =$W9&X9 -> 1章2課25 | AJ9: =$W9&Y9 -> 1章2課26 | AK9: =$W9&Z9 -> 1章2課27 | AL9: =$W9&AA9 -> 1章2課28 | AM9: =$W9&AB9 -> 1章2課29 | AN9: =$W9&AC9 -> 1章2課30 | AO9: =$W9&AD9 -> 1章2課31 | AP9: =$W9&AE9 -> 1章2課32
A10: =IF($X10=1,$A9+1,$A9) -> 2 | B10: =IF(V10="",$B9,$V10) -> 1章2課 | C10: =IFERROR(VLOOKUP($B10&"_"&X10,Raw_data_N2_Kanji[[Receipe no]:[Receipe]],4,0),"") | D10: =IFERROR(VLOOKUP($B10&"_"&Y10,Raw_data_N2_Kanji[[Receipe no]:[Receipe]],4,0),"") | E10: =IFERROR(VLOOKUP($B10&"_"&Z10,Raw_data_N2_Kanji[[Receipe no]:[Receipe]],4,0),"") | F10: =IFERROR(VLOOKUP($B10&"_"&AA10,Raw_data_N2_Kanji[[Receipe no]:[Receipe]],4,0),"") | G10: =IFERROR(VLOOKUP($B10&"_"&AB10,Raw_data_N2_Kanji[[Receipe no]:[Receipe]],4,0),"") | H10: =IFERROR(VLOOKUP($B10&"_"&AC10,Raw_data_N2_Kanji[[Receipe no]:[Receipe]],4,0),"") | I10: =IFERROR(VLOOKUP($B10&"_"&AD10,Raw_data_N2_Kanji[[Receipe no]:[Receipe]],4,0),"") | J10: =IFERROR(VLOOKUP($B10&"_"&AE10,Raw_data_N2_Kanji[[Receipe no]:[Receipe]],4,0),"") | L10: =$W10 -> 1章2課 | M10: =IFERROR(VLOOKUP($L10&"_"&X10,Final_manabou_kanji[],6,0),"") | N10: =IFERROR(VLOOKUP($L10&"_"&Y10,Final_manabou_kanji[],6,0),"") | O10: =IFERROR(VLOOKUP($L10&"_"&Z10,Final_manabou_kanji[],6,0),"") | P10: =IFERROR(VLOOKUP($L10&"_"&AA10,Final_manabou_kanji[],6,0),"") | Q10: =IFERROR(VLOOKUP($L10&"_"&AB10,Final_manabou_kanji[],6,0),"") | R10: =IFERROR(VLOOKUP($L10&"_"&AC10,Final_manabou_kanji[],6,0),"") | S10: =IFERROR(VLOOKUP($L10&"_"&AD10,Final_manabou_kanji[],6,0),"") | T10: =IFERROR(VLOOKUP($L10&"_"&AE10,Final_manabou_kanji[],6,0),"") | W10: =IF(V10="",$W9,$V10) -> 1章2課 | X10: =IF($V10="",X9+8,X$1) -> 33 | Y10: =IF($V10="",Y9+8,Y$1) -> 34 | Z10: =IF($V10="",Z9+8,Z$1) -> 35 | AA10: =IF($V10="",AA9+8,AA$1) -> 36 | AB10: =IF($V10="",AB9+8,AB$1) -> 37 | AC10: =IF($V10="",AC9+8,AC$1) -> 38 | AD10: =IF($V10="",AD9+8,AD$1) -> 39 | AE10: =IF($V10="",AE9+8,AE$1) -> 40 | AH10: 22 | AI10: =$W10&X10 -> 1章2課33 | AJ10: =$W10&Y10 -> 1章2課34 | AK10: =$W10&Z10 -> 1章2課35 | AL10: =$W10&AA10 -> 1章2課36 | AM10: =$W10&AB10 -> 1章2課37 | AN10: =$W10&AC10 -> 1章2課38 | AO10: =$W10&AD10 -> 1章2課39 | AP10: =$W10&AE10 -> 1章2課40
A11: =IF($X11=1,$A10+1,$A10) -> 3 | B11: =IF(V11="",$B10,$V11) -> 1章3課 | C11: =IFERROR(VLOOKUP($B11&"_"&X11,Raw_data_N2_Kanji[[Receipe no]:[Receipe]],4,0),"") | D11: =IFERROR(VLOOKUP($B11&"_"&Y11,Raw_data_N2_Kanji[[Receipe no]:[Receipe]],4,0),"") | E11: =IFERROR(VLOOKUP($B11&"_"&Z11,Raw_data_N2_Kanji[[Receipe no]:[Receipe]],4,0),"") | F11: =IFERROR(VLOOKUP($B11&"_"&AA11,Raw_data_N2_Kanji[[Receipe no]:[Receipe]],4,0),"") | G11: =IFERROR(VLOOKUP($B11&"_"&AB11,Raw_data_N2_Kanji[[Receipe no]:[Receipe]],4,0),"") | H11: =IFERROR(VLOOKUP($B11&"_"&AC11,Raw_data_N2_Kanji[[Receipe no]:[Receipe]],4,0),"") | I11: =IFERROR(VLOOKUP($B11&"_"&AD11,Raw_data_N2_Kanji[[Receipe no]:[Receipe]],4,0),"") | J11: =IFERROR(VLOOKUP($B11&"_"&AE11,Raw_data_N2_Kanji[[Receipe no]:[Receipe]],4,0),"") | L11: =$W11 -> 1章3課 | M11: =IFERROR(VLOOKUP($L11&"_"&X11,Final_manabou_kanji[],6,0),"") | N11: =IFERROR(VLOOKUP($L11&"_"&Y11,Final_manabou_kanji[],6,0),"") | O11: =IFERROR(VLOOKUP($L11&"_"&Z11,Final_manabou_kanji[],6,0),"") | P11: =IFERROR(VLOOKUP($L11&"_"&AA11,Final_manabou_kanji[],6,0),"") | Q11: =IFERROR(VLOOKUP($L11&"_"&AB11,Final_manabou_kanji[],6,0),"") | R11: =IFERROR(VLOOKUP($L11&"_"&AC11,Final_manabou_kanji[],6,0),"") | S11: =IFERROR(VLOOKUP($L11&"_"&AD11,Final_manabou_kanji[],6,0),"") | T11: =IFERROR(VLOOKUP($L11&"_"&AE11,Final_manabou_kanji[],6,0),"") | V11: 1章3課 | W11: =IF(V11="",$W10,$V11) -> 1章3課 | X11: =IF($V11="",X10+8,X$1) -> 1 | Y11: =IF($V11="",Y10+8,Y$1) -> 2 | Z11: =IF($V11="",Z10+8,Z$1) -> 3 | AA11: =IF($V11="",AA10+8,AA$1) -> 4 | AB11: =IF($V11="",AB10+8,AB$1) -> 5 | AC11: =IF($V11="",AC10+8,AC$1) -> 6 | AD11: =IF($V11="",AD10+8,AD$1) -> 7 | AE11: =IF($V11="",AE10+8,AE$1) -> 8 | AH11: 22 | AI11: =$W11&X11 -> 1章3課1 | AJ11: =$W11&Y11 -> 1章3課2 | AK11: =$W11&Z11 -> 1章3課3 | AL11: =$W11&AA11 -> 1章3課4 | AM11: =$W11&AB11 -> 1章3課5 | AN11: =$W11&AC11 -> 1章3課6 | AO11: =$W11&AD11 -> 1章3課7 | AP11: =$W11&AE11 -> 1章3課8
A12: =IF($X12=1,$A11+1,$A11) -> 3 | B12: =IF(V12="",$B11,$V12) -> 1章3課 | C12: =IFERROR(VLOOKUP($B12&"_"&X12,Raw_data_N2_Kanji[[Receipe no]:[Receipe]],4,0),"") | D12: =IFERROR(VLOOKUP($B12&"_"&Y12,Raw_data_N2_Kanji[[Receipe no]:[Receipe]],4,0),"") | E12: =IFERROR(VLOOKUP($B12&"_"&Z12,Raw_data_N2_Kanji[[Receipe no]:[Receipe]],4,0),"") | F12: =IFERROR(VLOOKUP($B12&"_"&AA12,Raw_data_N2_Kanji[[Receipe no]:[Receipe]],4,0),"") | G12: =IFERROR(VLOOKUP($B12&"_"&AB12,Raw_data_N2_Kanji[[Receipe no]:[Receipe]],4,0),"") | H12: =IFERROR(VLOOKUP($B12&"_"&AC12,Raw_data_N2_Kanji[[Receipe no]:[Receipe]],4,0),"") | I12: =IFERROR(VLOOKUP($B12&"_"&AD12,Raw_data_N2_Kanji[[Receipe no]:[Receipe]],4,0),"") | J12: =IFERROR(VLOOKUP($B12&"_"&AE12,Raw_data_N2_Kanji[[Receipe no]:[Receipe]],4,0),"") | L12: =$W12 -> 1章3課 | M12: =IFERROR(VLOOKUP($L12&"_"&X12,Final_manabou_kanji[],6,0),"") | N12: =IFERROR(VLOOKUP($L12&"_"&Y12,Final_manabou_kanji[],6,0),"") | O12: =IFERROR(VLOOKUP($L12&"_"&Z12,Final_manabou_kanji[],6,0),"") | P12: =IFERROR(VLOOKUP($L12&"_"&AA12,Final_manabou_kanji[],6,0),"") | Q12: =IFERROR(VLOOKUP($L12&"_"&AB12,Final_manabou_kanji[],6,0),"") | R12: =IFERROR(VLOOKUP($L12&"_"&AC12,Final_manabou_kanji[],6,0),"") | S12: =IFERROR(VLOOKUP($L12&"_"&AD12,Final_manabou_kanji[],6,0),"") | T12: =IFERROR(VLOOKUP($L12&"_"&AE12,Final_manabou_kanji[],6,0),"") | W12: =IF(V12="",$W11,$V12) -> 1章3課 | X12: =IF($V12="",X11+8,X$1) -> 9 | Y12: =IF($V12="",Y11+8,Y$1) -> 10 | Z12: =IF($V12="",Z11+8,Z$1) -> 11 | AA12: =IF($V12="",AA11+8,AA$1) -> 12 | AB12: =IF($V12="",AB11+8,AB$1) -> 13 | AC12: =IF($V12="",AC11+8,AC$1) -> 14 | AD12: =IF($V12="",AD11+8,AD$1) -> 15 | AE12: =IF($V12="",AE11+8,AE$1) -> 16 | AH12: 22 | AI12: =$W12&X12 -> 1章3課9 | AJ12: =$W12&Y12 -> 1章3課10 | AK12: =$W12&Z12 -> 1章3課11 | AL12: =$W12&AA12 -> 1章3課12 | AM12: =$W12&AB12 -> 1章3課13 | AN12: =$W12&AC12 -> 1章3課14 | AO12: =$W12&AD12 -> 1章3課15 | AP12: =$W12&AE12 -> 1章3課16
A13: =IF($X13=1,$A12+1,$A12) -> 3 | B13: =IF(V13="",$B12,$V13) -> 1章3課 | C13: =IFERROR(VLOOKUP($B13&"_"&X13,Raw_data_N2_Kanji[[Receipe no]:[Receipe]],4,0),"") | D13: =IFERROR(VLOOKUP($B13&"_"&Y13,Raw_data_N2_Kanji[[Receipe no]:[Receipe]],4,0),"") | E13: =IFERROR(VLOOKUP($B13&"_"&Z13,Raw_data_N2_Kanji[[Receipe no]:[Receipe]],4,0),"") | F13: =IFERROR(VLOOKUP($B13&"_"&AA13,Raw_data_N2_Kanji[[Receipe no]:[Receipe]],4,0),"") | G13: =IFERROR(VLOOKUP($B13&"_"&AB13,Raw_data_N2_Kanji[[Receipe no]:[Receipe]],4,0),"") | H13: =IFERROR(VLOOKUP($B13&"_"&AC13,Raw_data_N2_Kanji[[Receipe no]:[Receipe]],4,0),"") | I13: =IFERROR(VLOOKUP($B13&"_"&AD13,Raw_data_N2_Kanji[[Receipe no]:[Receipe]],4,0),"") | J13: =IFERROR(VLOOKUP($B13&"_"&AE13,Raw_data_N2_Kanji[[Receipe no]:[Receipe]],4,0),"") | L13: =$W13 -> 1章3課 | M13: =IFERROR(VLOOKUP($L13&"_"&X13,Final_manabou_kanji[],6,0),"") | N13: =IFERROR(VLOOKUP($L13&"_"&Y13,Final_manabou_kanji[],6,0),"") | O13: =IFERROR(VLOOKUP($L13&"_"&Z13,Final_manabou_kanji[],6,0),"") | P13: =IFERROR(VLOOKUP($L13&"_"&AA13,Final_manabou_kanji[],6,0),"") | Q13: =IFERROR(VLOOKUP($L13&"_"&AB13,Final_manabou_kanji[],6,0),"") | R13: =IFERROR(VLOOKUP($L13&"_"&AC13,Final_manabou_kanji[],6,0),"") | S13: =IFERROR(VLOOKUP($L13&"_"&AD13,Final_manabou_kanji[],6,0),"") | T13: =IFERROR(VLOOKUP($L13&"_"&AE13,Final_manabou_kanji[],6,0),"") | W13: =IF(V13="",$W12,$V13) -> 1章3課 | X13: =IF($V13="",X12+8,X$1) -> 17 | Y13: =IF($V13="",Y12+8,Y$1) -> 18 | Z13: =IF($V13="",Z12+8,Z$1) -> 19 | AA13: =IF($V13="",AA12+8,AA$1) -> 20 | AB13: =IF($V13="",AB12+8,AB$1) -> 21 | AC13: =IF($V13="",AC12+8,AC$1) -> 22 | AD13: =IF($V13="",AD12+8,AD$1) -> 23 | AE13: =IF($V13="",AE12+8,AE$1) -> 24 | AH13: 22 | AI13: =$W13&X13 -> 1章3課17 | AJ13: =$W13&Y13 -> 1章3課18 | AK13: =$W13&Z13 -> 1章3課19 | AL13: =$W13&AA13 -> 1章3課20 | AM13: =$W13&AB13 -> 1章3課21 | AN13: =$W13&AC13 -> 1章3課22 | AO13: =$W13&AD13 -> 1章3課23 | AP13: =$W13&AE13 -> 1章3課24
A14: =IF($X14=1,$A13+1,$A13) -> 3 | B14: =IF(V14="",$B13,$V14) -> 1章3課 | C14: =IFERROR(VLOOKUP($B14&"_"&X14,Raw_data_N2_Kanji[[Receipe no]:[Receipe]],4,0),"") | D14: =IFERROR(VLOOKUP($B14&"_"&Y14,Raw_data_N2_Kanji[[Receipe no]:[Receipe]],4,0),"") | E14: =IFERROR(VLOOKUP($B14&"_"&Z14,Raw_data_N2_Kanji[[Receipe no]:[Receipe]],4,0),"") | F14: =IFERROR(VLOOKUP($B14&"_"&AA14,Raw_data_N2_Kanji[[Receipe no]:[Receipe]],4,0),"") | G14: =IFERROR(VLOOKUP($B14&"_"&AB14,Raw_data_N2_Kanji[[Receipe no]:[Receipe]],4,0),"") | H14: =IFERROR(VLOOKUP($B14&"_"&AC14,Raw_data_N2_Kanji[[Receipe no]:[Receipe]],4,0),"") | I14: =IFERROR(VLOOKUP($B14&"_"&AD14,Raw_data_N2_Kanji[[Receipe no]:[Receipe]],4,0),"") | J14: =IFERROR(VLOOKUP($B14&"_"&AE14,Raw_data_N2_Kanji[[Receipe no]:[Receipe]],4,0),"") | L14: =$W14 -> 1章3課 | M14: =IFERROR(VLOOKUP($L14&"_"&X14,Final_manabou_kanji[],6,0),"") | N14: =IFERROR(VLOOKUP($L14&"_"&Y14,Final_manabou_kanji[],6,0),"") | O14: =IFERROR(VLOOKUP($L14&"_"&Z14,Final_manabou_kanji[],6,0),"") | P14: =IFERROR(VLOOKUP($L14&"_"&AA14,Final_manabou_kanji[],6,0),"") | Q14: =IFERROR(VLOOKUP($L14&"_"&AB14,Final_manabou_kanji[],6,0),"") | R14: =IFERROR(VLOOKUP($L14&"_"&AC14,Final_manabou_kanji[],6,0),"") | S14: =IFERROR(VLOOKUP($L14&"_"&AD14,Final_manabou_kanji[],6,0),"") | T14: =IFERROR(VLOOKUP($L14&"_"&AE14,Final_manabou_kanji[],6,0),"") | W14: =IF(V14="",$W13,$V14) -> 1章3課 | X14: =IF($V14="",X13+8,X$1) -> 25 | Y14: =IF($V14="",Y13+8,Y$1) -> 26 | Z14: =IF($V14="",Z13+8,Z$1) -> 27 | AA14: =IF($V14="",AA13+8,AA$1) -> 28 | AB14: =IF($V14="",AB13+8,AB$1) -> 29 | AC14: =IF($V14="",AC13+8,AC$1) -> 30 | AD14: =IF($V14="",AD13+8,AD$1) -> 31 | AE14: =IF($V14="",AE13+8,AE$1) -> 32 | AH14: 22 | AI14: =$W14&X14 -> 1章3課25 | AJ14: =$W14&Y14 -> 1章3課26 | AK14: =$W14&Z14 -> 1章3課27 | AL14: =$W14&AA14 -> 1章3課28 | AM14: =$W14&AB14 -> 1章3課29 | AN14: =$W14&AC14 -> 1章3課30 | AO14: =$W14&AD14 -> 1章3課31 | AP14: =$W14&AE14 -> 1章3課32
A15: =IF($X15=1,$A14+1,$A14) -> 3 | B15: =IF(V15="",$B14,$V15) -> 1章3課 | C15: =IFERROR(VLOOKUP($B15&"_"&X15,Raw_data_N2_Kanji[[Receipe no]:[Receipe]],4,0),"") | D15: =IFERROR(VLOOKUP($B15&"_"&Y15,Raw_data_N2_Kanji[[Receipe no]:[Receipe]],4,0),"") | E15: =IFERROR(VLOOKUP($B15&"_"&Z15,Raw_data_N2_Kanji[[Receipe no]:[Receipe]],4,0),"") | F15: =IFERROR(VLOOKUP($B15&"_"&AA15,Raw_data_N2_Kanji[[Receipe no]:[Receipe]],4,0),"") | G15: =IFERROR(VLOOKUP($B15&"_"&AB15,Raw_data_N2_Kanji[[Receipe no]:[Receipe]],4,0),"") | H15: =IFERROR(VLOOKUP($B15&"_"&AC15,Raw_data_N2_Kanji[[Receipe no]:[Receipe]],4,0),"") | I15: =IFERROR(VLOOKUP($B15&"_"&AD15,Raw_data_N2_Kanji[[Receipe no]:[Receipe]],4,0),"") | J15: =IFERROR(VLOOKUP($B15&"_"&AE15,Raw_data_N2_Kanji[[Receipe no]:[Receipe]],4,0),"") | L15: =$W15 -> 1章3課 | M15: =IFERROR(VLOOKUP($L15&"_"&X15,Final_manabou_kanji[],6,0),"") | N15: =IFERROR(VLOOKUP($L15&"_"&Y15,Final_manabou_kanji[],6,0),"") | O15: =IFERROR(VLOOKUP($L15&"_"&Z15,Final_manabou_kanji[],6,0),"") | P15: =IFERROR(VLOOKUP($L15&"_"&AA15,Final_manabou_kanji[],6,0),"") | Q15: =IFERROR(VLOOKUP($L15&"_"&AB15,Final_manabou_kanji[],6,0),"") | R15: =IFERROR(VLOOKUP($L15&"_"&AC15,Final_manabou_kanji[],6,0),"") | S15: =IFERROR(VLOOKUP($L15&"_"&AD15,Final_manabou_kanji[],6,0),"") | T15: =IFERROR(VLOOKUP($L15&"_"&AE15,Final_manabou_kanji[],6,0),"") | W15: =IF(V15="",$W14,$V15) -> 1章3課 | X15: =IF($V15="",X14+8,X$1) -> 33 | Y15: =IF($V15="",Y14+8,Y$1) -> 34 | Z15: =IF($V15="",Z14+8,Z$1) -> 35 | AA15: =IF($V15="",AA14+8,AA$1) -> 36 | AB15: =IF($V15="",AB14+8,AB$1) -> 37 | AC15: =IF($V15="",AC14+8,AC$1) -> 38 | AD15: =IF($V15="",AD14+8,AD$1) -> 39 | AE15: =IF($V15="",AE14+8,AE$1) -> 40 | AH15: 22 | AI15: =$W15&X15 -> 1章3課33 | AJ15: =$W15&Y15 -> 1章3課34 | AK15: =$W15&Z15 -> 1章3課35 | AL15: =$W15&AA15 -> 1章3課36 | AM15: =$W15&AB15 -> 1章3課37 | AN15: =$W15&AC15 -> 1章3課38 | AO15: =$W15&AD15 -> 1章3課39 | AP15: =$W15&AE15 -> 1章3課40
A16: =IF($X16=1,$A15+1,$A15) -> 3 | B16: =IF(V16="",$B15,$V16) -> 1章3課 | C16: =IFERROR(VLOOKUP($B16&"_"&X16,Raw_data_N2_Kanji[[Receipe no]:[Receipe]],4,0),"") | D16: =IFERROR(VLOOKUP($B16&"_"&Y16,Raw_data_N2_Kanji[[Receipe no]:[Receipe]],4,0),"") | E16: =IFERROR(VLOOKUP($B16&"_"&Z16,Raw_data_N2_Kanji[[Receipe no]:[Receipe]],4,0),"") | F16: =IFERROR(VLOOKUP($B16&"_"&AA16,Raw_data_N2_Kanji[[Receipe no]:[Receipe]],4,0),"") | G16: =IFERROR(VLOOKUP($B16&"_"&AB16,Raw_data_N2_Kanji[[Receipe no]:[Receipe]],4,0),"") | H16: =IFERROR(VLOOKUP($B16&"_"&AC16,Raw_data_N2_Kanji[[Receipe no]:[Receipe]],4,0),"") | I16: =IFERROR(VLOOKUP($B16&"_"&AD16,Raw_data_N2_Kanji[[Receipe no]:[Receipe]],4,0),"") | J16: =IFERROR(VLOOKUP($B16&"_"&AE16,Raw_data_N2_Kanji[[Receipe no]:[Receipe]],4,0),"") | L16: =$W16 -> 1章3課 | M16: =IFERROR(VLOOKUP($L16&"_"&X16,Final_manabou_kanji[],6,0),"") | N16: =IFERROR(VLOOKUP($L16&"_"&Y16,Final_manabou_kanji[],6,0),"") | O16: =IFERROR(VLOOKUP($L16&"_"&Z16,Final_manabou_kanji[],6,0),"") | P16: =IFERROR(VLOOKUP($L16&"_"&AA16,Final_manabou_kanji[],6,0),"") | Q16: =IFERROR(VLOOKUP($L16&"_"&AB16,Final_manabou_kanji[],6,0),"") | R16: =IFERROR(VLOOKUP($L16&"_"&AC16,Final_manabou_kanji[],6,0),"") | S16: =IFERROR(VLOOKUP($L16&"_"&AD16,Final_manabou_kanji[],6,0),"") | T16: =IFERROR(VLOOKUP($L16&"_"&AE16,Final_manabou_kanji[],6,0),"") | W16: =IF(V16="",$W15,$V16) -> 1章3課 | X16: =IF($V16="",X15+8,X$1) -> 41 | Y16: =IF($V16="",Y15+8,Y$1) -> 42 | Z16: =IF($V16="",Z15+8,Z$1) -> 43 | AA16: =IF($V16="",AA15+8,AA$1) -> 44 | AB16: =IF($V16="",AB15+8,AB$1) -> 45 | AC16: =IF($V16="",AC15+8,AC$1) -> 46 | AD16: =IF($V16="",AD15+8,AD$1) -> 47 | AE16: =IF($V16="",AE15+8,AE$1) -> 48 | AH16: 23 | AI16: =$W16&X16 -> 1章3課41 | AJ16: =$W16&Y16 -> 1章3課42 | AK16: =$W16&Z16 -> 1章3課43 | AL16: =$W16&AA16 -> 1章3課44 | AM16: =$W16&AB16 -> 1章3課45 | AN16: =$W16&AC16 -> 1章3課46 | AO16: =$W16&AD16 -> 1章3課47 | AP16: =$W16&AE16 -> 1章3課48
A17: =IF($X17=1,$A16+1,$A16) -> 4 | B17: =IF(V17="",$B16,$V17) -> 1章4課 | C17: =IFERROR(VLOOKUP($B17&"_"&X17,Raw_data_N2_Kanji[[Receipe no]:[Receipe]],4,0),"") | D17: =IFERROR(VLOOKUP($B17&"_"&Y17,Raw_data_N2_Kanji[[Receipe no]:[Receipe]],4,0),"") | E17: =IFERROR(VLOOKUP($B17&"_"&Z17,Raw_data_N2_Kanji[[Receipe no]:[Receipe]],4,0),"") | F17: =IFERROR(VLOOKUP($B17&"_"&AA17,Raw_data_N2_Kanji[[Receipe no]:[Receipe]],4,0),"") | G17: =IFERROR(VLOOKUP($B17&"_"&AB17,Raw_data_N2_Kanji[[Receipe no]:[Receipe]],4,0),"") | H17: =IFERROR(VLOOKUP($B17&"_"&AC17,Raw_data_N2_Kanji[[Receipe no]:[Receipe]],4,0),"") | I17: =IFERROR(VLOOKUP($B17&"_"&AD17,Raw_data_N2_Kanji[[Receipe no]:[Receipe]],4,0),"") | J17: =IFERROR(VLOOKUP($B17&"_"&AE17,Raw_data_N2_Kanji[[Receipe no]:[Receipe]],4,0),"") | L17: =$W17 -> 1章4課 | M17: =IFERROR(VLOOKUP($L17&"_"&X17,Final_manabou_kanji[],6,0),"") | N17: =IFERROR(VLOOKUP($L17&"_"&Y17,Final_manabou_kanji[],6,0),"") | O17: =IFERROR(VLOOKUP($L17&"_"&Z17,Final_manabou_kanji[],6,0),"") | P17: =IFERROR(VLOOKUP($L17&"_"&AA17,Final_manabou_kanji[],6,0),"") | Q17: =IFERROR(VLOOKUP($L17&"_"&AB17,Final_manabou_kanji[],6,0),"") | R17: =IFERROR(VLOOKUP($L17&"_"&AC17,Final_manabou_kanji[],6,0),"") | S17: =IFERROR(VLOOKUP($L17&"_"&AD17,Final_manabou_kanji[],6,0),"") | T17: =IFERROR(VLOOKUP($L17&"_"&AE17,Final_manabou_kanji[],6,0),"") | V17: 1章4課 | W17: =IF(V17="",$W16,$V17) -> 1章4課 | X17: =IF($V17="",X16+8,X$1) -> 1 | Y17: =IF($V17="",Y16+8,Y$1) -> 2 | Z17: =IF($V17="",Z16+8,Z$1) -> 3 | AA17: =IF($V17="",AA16+8,AA$1) -> 4 | AB17: =IF($V17="",AB16+8,AB$1) -> 5 | AC17: =IF($V17="",AC16+8,AC$1) -> 6 | AD17: =IF($V17="",AD16+8,AD$1) -> 7 | AE17: =IF($V17="",AE16+8,AE$1) -> 8 | AH17: 23 | AI17: =$W17&X17 -> 1章4課1 | AJ17: =$W17&Y17 -> 1章4課2 | AK17: =$W17&Z17 -> 1章4課3 | AL17: =$W17&AA17 -> 1章4課4 | AM17: =$W17&AB17 -> 1章4課5 | AN17: =$W17&AC17 -> 1章4課6 | AO17: =$W17&AD17 -> 1章4課7 | AP17: =$W17&AE17 -> 1章4課8
A18: =IF($X18=1,$A17+1,$A17) -> 4 | B18: =IF(V18="",$B17,$V18) -> 1章4課 | C18: =IFERROR(VLOOKUP($B18&"_"&X18,Raw_data_N2_Kanji[[Receipe no]:[Receipe]],4,0),"") | D18: =IFERROR(VLOOKUP($B18&"_"&Y18,Raw_data_N2_Kanji[[Receipe no]:[Receipe]],4,0),"") | E18: =IFERROR(VLOOKUP($B18&"_"&Z18,Raw_data_N2_Kanji[[Receipe no]:[Receipe]],4,0),"") | F18: =IFERROR(VLOOKUP($B18&"_"&AA18,Raw_data_N2_Kanji[[Receipe no]:[Receipe]],4,0),"") | G18: =IFERROR(VLOOKUP($B18&"_"&AB18,Raw_data_N2_Kanji[[Receipe no]:[Receipe]],4,0),"") | H18: =IFERROR(VLOOKUP($B18&"_"&AC18,Raw_data_N2_Kanji[[Receipe no]:[Receipe]],4,0),"") | I18: =IFERROR(VLOOKUP($B18&"_"&AD18,Raw_data_N2_Kanji[[Receipe no]:[Receipe]],4,0),"") | J18: =IFERROR(VLOOKUP($B18&"_"&AE18,Raw_data_N2_Kanji[[Receipe no]:[Receipe]],4,0),"") | L18: =$W18 -> 1章4課 | M18: =IFERROR(VLOOKUP($L18&"_"&X18,Final_manabou_kanji[],6,0),"") | N18: =IFERROR(VLOOKUP($L18&"_"&Y18,Final_manabou_kanji[],6,0),"") | O18: =IFERROR(VLOOKUP($L18&"_"&Z18,Final_manabou_kanji[],6,0),"") | P18: =IFERROR(VLOOKUP($L18&"_"&AA18,Final_manabou_kanji[],6,0),"") | Q18: =IFERROR(VLOOKUP($L18&"_"&AB18,Final_manabou_kanji[],6,0),"") | R18: =IFERROR(VLOOKUP($L18&"_"&AC18,Final_manabou_kanji[],6,0),"") | S18: =IFERROR(VLOOKUP($L18&"_"&AD18,Final_manabou_kanji[],6,0),"") | T18: =IFERROR(VLOOKUP($L18&"_"&AE18,Final_manabou_kanji[],6,0),"") | W18: =IF(V18="",$W17,$V18) -> 1章4課 | X18: =IF($V18="",X17+8,X$1) -> 9 | Y18: =IF($V18="",Y17+8,Y$1) -> 10 | Z18: =IF($V18="",Z17+8,Z$1) -> 11 | AA18: =IF($V18="",AA17+8,AA$1) -> 12 | AB18: =IF($V18="",AB17+8,AB$1) -> 13 | AC18: =IF($V18="",AC17+8,AC$1) -> 14 | AD18: =IF($V18="",AD17+8,AD$1) -> 15 | AE18: =IF($V18="",AE17+8,AE$1) -> 16 | AH18: 23 | AI18: =$W18&X18 -> 1章4課9 | AJ18: =$W18&Y18 -> 1章4課10 | AK18: =$W18&Z18 -> 1章4課11 | AL18: =$W18&AA18 -> 1章4課12 | AM18: =$W18&AB18 -> 1章4課13 | AN18: =$W18&AC18 -> 1章4課14 | AO18: =$W18&AD18 -> 1章4課15 | AP18: =$W18&AE18 -> 1章4課16
A19: =IF($X19=1,$A18+1,$A18) -> 4 | B19: =IF(V19="",$B18,$V19) -> 1章4課 | C19: =IFERROR(VLOOKUP($B19&"_"&X19,Raw_data_N2_Kanji[[Receipe no]:[Receipe]],4,0),"") | D19: =IFERROR(VLOOKUP($B19&"_"&Y19,Raw_data_N2_Kanji[[Receipe no]:[Receipe]],4,0),"") | E19: =IFERROR(VLOOKUP($B19&"_"&Z19,Raw_data_N2_Kanji[[Receipe no]:[Receipe]],4,0),"") | F19: =IFERROR(VLOOKUP($B19&"_"&AA19,Raw_data_N2_Kanji[[Receipe no]:[Receipe]],4,0),"") | G19: =IFERROR(VLOOKUP($B19&"_"&AB19,Raw_data_N2_Kanji[[Receipe no]:[Receipe]],4,0),"") | H19: =IFERROR(VLOOKUP($B19&"_"&AC19,Raw_data_N2_Kanji[[Receipe no]:[Receipe]],4,0),"") | I19: =IFERROR(VLOOKUP($B19&"_"&AD19,Raw_data_N2_Kanji[[Receipe no]:[Receipe]],4,0),"") | J19: =IFERROR(VLOOKUP($B19&"_"&AE19,Raw_data_N2_Kanji[[Receipe no]:[Receipe]],4,0),"") | L19: =$W19 -> 1章4課 | M19: =IFERROR(VLOOKUP($L19&"_"&X19,Final_manabou_kanji[],6,0),"") | N19: =IFERROR(VLOOKUP($L19&"_"&Y19,Final_manabou_kanji[],6,0),"") | O19: =IFERROR(VLOOKUP($L19&"_"&Z19,Final_manabou_kanji[],6,0),"") | P19: =IFERROR(VLOOKUP($L19&"_"&AA19,Final_manabou_kanji[],6,0),"") | Q19: =IFERROR(VLOOKUP($L19&"_"&AB19,Final_manabou_kanji[],6,0),"") | R19: =IFERROR(VLOOKUP($L19&"_"&AC19,Final_manabou_kanji[],6,0),"") | S19: =IFERROR(VLOOKUP($L19&"_"&AD19,Final_manabou_kanji[],6,0),"") | T19: =IFERROR(VLOOKUP($L19&"_"&AE19,Final_manabou_kanji[],6,0),"") | W19: =IF(V19="",$W18,$V19) -> 1章4課 | X19: =IF($V19="",X18+8,X$1) -> 17 | Y19: =IF($V19="",Y18+8,Y$1) -> 18 | Z19: =IF($V19="",Z18+8,Z$1) -> 19 | AA19: =IF($V19="",AA18+8,AA$1) -> 20 | AB19: =IF($V19="",AB18+8,AB$1) -> 21 | AC19: =IF($V19="",AC18+8,AC$1) -> 22 | AD19: =IF($V19="",AD18+8,AD$1) -> 23 | AE19: =IF($V19="",AE18+8,AE$1) -> 24 | AH19: 23 | AI19: =$W19&X19 -> 1章4課17 | AJ19: =$W19&Y19 -> 1章4課18 | AK19: =$W19&Z19 -> 1章4課19 | AL19: =$W19&AA19 -> 1章4課20 | AM19: =$W19&AB19 -> 1章4課21 | AN19: =$W19&AC19 -> 1章4課22 | AO19: =$W19&AD19 -> 1章4課23 | AP19: =$W19&AE19 -> 1章4課24
A20: =IF($X20=1,$A19+1,$A19) -> 4 | B20: =IF(V20="",$B19,$V20) -> 1章4課 | C20: =IFERROR(VLOOKUP($B20&"_"&X20,Raw_data_N2_Kanji[[Receipe no]:[Receipe]],4,0),"") | D20: =IFERROR(VLOOKUP($B20&"_"&Y20,Raw_data_N2_Kanji[[Receipe no]:[Receipe]],4,0),"") | E20: =IFERROR(VLOOKUP($B20&"_"&Z20,Raw_data_N2_Kanji[[Receipe no]:[Receipe]],4,0),"") | F20: =IFERROR(VLOOKUP($B20&"_"&AA20,Raw_data_N2_Kanji[[Receipe no]:[Receipe]],4,0),"") | G20: =IFERROR(VLOOKUP($B20&"_"&AB20,Raw_data_N2_Kanji[[Receipe no]:[Receipe]],4,0),"") | H20: =IFERROR(VLOOKUP($B20&"_"&AC20,Raw_data_N2_Kanji[[Receipe no]:[Receipe]],4,0),"") | I20: =IFERROR(VLOOKUP($B20&"_"&AD20,Raw_data_N2_Kanji[[Receipe no]:[Receipe]],4,0),"") | J20: =IFERROR(VLOOKUP($B20&"_"&AE20,Raw_data_N2_Kanji[[Receipe no]:[Receipe]],4,0),"") | L20: =$W20 -> 1章4課 | M20: =IFERROR(VLOOKUP($L20&"_"&X20,Final_manabou_kanji[],6,0),"") | N20: =IFERROR(VLOOKUP($L20&"_"&Y20,Final_manabou_kanji[],6,0),"") | O20: =IFERROR(VLOOKUP($L20&"_"&Z20,Final_manabou_kanji[],6,0),"") | P20: =IFERROR(VLOOKUP($L20&"_"&AA20,Final_manabou_kanji[],6,0),"") | Q20: =IFERROR(VLOOKUP($L20&"_"&AB20,Final_manabou_kanji[],6,0),"") | R20: =IFERROR(VLOOKUP($L20&"_"&AC20,Final_manabou_kanji[],6,0),"") | S20: =IFERROR(VLOOKUP($L20&"_"&AD20,Final_manabou_kanji[],6,0),"") | T20: =IFERROR(VLOOKUP($L20&"_"&AE20,Final_manabou_kanji[],6,0),"") | W20: =IF(V20="",$W19,$V20) -> 1章4課 | X20: =IF($V20="",X19+8,X$1) -> 25 | Y20: =IF($V20="",Y19+8,Y$1) -> 26 | Z20: =IF($V20="",Z19+8,Z$1) -> 27 | AA20: =IF($V20="",AA19+8,AA$1) -> 28 | AB20: =IF($V20="",AB19+8,AB$1) -> 29 | AC20: =IF($V20="",AC19+8,AC$1) -> 30 | AD20: =IF($V20="",AD19+8,AD$1) -> 31 | AE20: =IF($V20="",AE19+8,AE$1) -> 32 | AH20: 23 | AI20: =$W20&X20 -> 1章4課25 | AJ20: =$W20&Y20 -> 1章4課26 | AK20: =$W20&Z20 -> 1章4課27 | AL20: =$W20&AA20 -> 1章4課28 | AM20: =$W20&AB20 -> 1章4課29 | AN20: =$W20&AC20 -> 1章4課30 | AO20: =$W20&AD20 -> 1章4課31 | AP20: =$W20&AE20 -> 1章4課32
A21: =IF($X21=1,$A20+1,$A20) -> 5 | B21: =IF(V21="",$B20,$V21) -> 2章1課 | C21: =IFERROR(VLOOKUP($B21&"_"&X21,Raw_data_N2_Kanji[[Receipe no]:[Receipe]],4,0),"") | D21: =IFERROR(VLOOKUP($B21&"_"&Y21,Raw_data_N2_Kanji[[Receipe no]:[Receipe]],4,0),"") | E21: =IFERROR(VLOOKUP($B21&"_"&Z21,Raw_data_N2_Kanji[[Receipe no]:[Receipe]],4,0),"") | F21: =IFERROR(VLOOKUP($B21&"_"&AA21,Raw_data_N2_Kanji[[Receipe no]:[Receipe]],4,0),"") | G21: =IFERROR(VLOOKUP($B21&"_"&AB21,Raw_data_N2_Kanji[[Receipe no]:[Receipe]],4,0),"") | H21: =IFERROR(VLOOKUP($B21&"_"&AC21,Raw_data_N2_Kanji[[Receipe no]:[Receipe]],4,0),"") | I21: =IFERROR(VLOOKUP($B21&"_"&AD21,Raw_data_N2_Kanji[[Receipe no]:[Receipe]],4,0),"") | J21: =IFERROR(VLOOKUP($B21&"_"&AE21,Raw_data_N2_Kanji[[Receipe no]:[Receipe]],4,0),"") | L21: =$W21 -> 2章1課 | M21: =IFERROR(VLOOKUP($L21&"_"&X21,Final_manabou_kanji[],6,0),"") | N21: =IFERROR(VLOOKUP($L21&"_"&Y21,Final_manabou_kanji[],6,0),"") | O21: =IFERROR(VLOOKUP($L21&"_"&Z21,Final_manabou_kanji[],6,0),"") | P21: =IFERROR(VLOOKUP($L21&"_"&AA21,Final_manabou_kanji[],6,0),"") | Q21: =IFERROR(VLOOKUP($L21&"_"&AB21,Final_manabou_kanji[],6,0),"") | R21: =IFERROR(VLOOKUP($L21&"_"&AC21,Final_manabou_kanji[],6,0),"") | S21: =IFERROR(VLOOKUP($L21&"_"&AD21,Final_manabou_kanji[],6,0),"") | T21: =IFERROR(VLOOKUP($L21&"_"&AE21,Final_manabou_kanji[],6,0),"") | V21: 2章1課 | W21: =IF(V21="",$W20,$V21) -> 2章1課 | X21: =IF($V21="",X20+8,X$1) -> 1 | Y21: =IF($V21="",Y20+8,Y$1) -> 2 | Z21: =IF($V21="",Z20+8,Z$1) -> 3 | AA21: =IF($V21="",AA20+8,AA$1) -> 4 | AB21: =IF($V21="",AB20+8,AB$1) -> 5 | AC21: =IF($V21="",AC20+8,AC$1) -> 6 | AD21: =IF($V21="",AD20+8,AD$1) -> 7 | AE21: =IF($V21="",AE20+8,AE$1) -> 8 | AH21: 23 | AI21: =$W21&X21 -> 2章1課1 | AJ21: =$W21&Y21 -> 2章1課2 | AK21: =$W21&Z21 -> 2章1課3 | AL21: =$W21&AA21 -> 2章1課4 | AM21: =$W21&AB21 -> 2章1課5 | AN21: =$W21&AC21 -> 2章1課6 | AO21: =$W21&AD21 -> 2章1課7 | AP21: =$W21&AE21 -> 2章1課8
A22: =IF($X22=1,$A21+1,$A21) -> 5 | B22: =IF(V22="",$B21,$V22) -> 2章1課 | C22: =IFERROR(VLOOKUP($B22&"_"&X22,Raw_data_N2_Kanji[[Receipe no]:[Receipe]],4,0),"") | D22: =IFERROR(VLOOKUP($B22&"_"&Y22,Raw_data_N2_Kanji[[Receipe no]:[Receipe]],4,0),"") | E22: =IFERROR(VLOOKUP($B22&"_"&Z22,Raw_data_N2_Kanji[[Receipe no]:[Receipe]],4,0),"") | F22: =IFERROR(VLOOKUP($B22&"_"&AA22,Raw_data_N2_Kanji[[Receipe no]:[Receipe]],4,0),"") | G22: =IFERROR(VLOOKUP($B22&"_"&AB22,Raw_data_N2_Kanji[[Receipe no]:[Receipe]],4,0),"") | H22: =IFERROR(VLOOKUP($B22&"_"&AC22,Raw_data_N2_Kanji[[Receipe no]:[Receipe]],4,0),"") | I22: =IFERROR(VLOOKUP($B22&"_"&AD22,Raw_data_N2_Kanji[[Receipe no]:[Receipe]],4,0),"") | J22: =IFERROR(VLOOKUP($B22&"_"&AE22,Raw_data_N2_Kanji[[Receipe no]:[Receipe]],4,0),"") | L22: =$W22 -> 2章1課 | M22: =IFERROR(VLOOKUP($L22&"_"&X22,Final_manabou_kanji[],6,0),"") | N22: =IFERROR(VLOOKUP($L22&"_"&Y22,Final_manabou_kanji[],6,0),"") | O22: =IFERROR(VLOOKUP($L22&"_"&Z22,Final_manabou_kanji[],6,0),"") | P22: =IFERROR(VLOOKUP($L22&"_"&AA22,Final_manabou_kanji[],6,0),"") | Q22: =IFERROR(VLOOKUP($L22&"_"&AB22,Final_manabou_kanji[],6,0),"") | R22: =IFERROR(VLOOKUP($L22&"_"&AC22,Final_manabou_kanji[],6,0),"") | S22: =IFERROR(VLOOKUP($L22&"_"&AD22,Final_manabou_kanji[],6,0),"") | T22: =IFERROR(VLOOKUP($L22&"_"&AE22,Final_manabou_kanji[],6,0),"") | W22: =IF(V22="",$W21,$V22) -> 2章1課 | X22: =IF($V22="",X21+8,X$1) -> 9 | Y22: =IF($V22="",Y21+8,Y$1) -> 10 | Z22: =IF($V22="",Z21+8,Z$1) -> 11 | AA22: =IF($V22="",AA21+8,AA$1) -> 12 | AB22: =IF($V22="",AB21+8,AB$1) -> 13 | AC22: =IF($V22="",AC21+8,AC$1) -> 14 | AD22: =IF($V22="",AD21+8,AD$1) -> 15 | AE22: =IF($V22="",AE21+8,AE$1) -> 16 | AH22: 23 | AI22: =$W22&X22 -> 2章1課9 | AJ22: =$W22&Y22 -> 2章1課10 | AK22: =$W22&Z22 -> 2章1課11 | AL22: =$W22&AA22 -> 2章1課12 | AM22: =$W22&AB22 -> 2章1課13 | AN22: =$W22&AC22 -> 2章1課14 | AO22: =$W22&AD22 -> 2章1課15 | AP22: =$W22&AE22 -> 2章1課16
A23: =IF($X23=1,$A22+1,$A22) -> 5 | B23: =IF(V23="",$B22,$V23) -> 2章1課 | C23: =IFERROR(VLOOKUP($B23&"_"&X23,Raw_data_N2_Kanji[[Receipe no]:[Receipe]],4,0),"") | D23: =IFERROR(VLOOKUP($B23&"_"&Y23,Raw_data_N2_Kanji[[Receipe no]:[Receipe]],4,0),"") | E23: =IFERROR(VLOOKUP($B23&"_"&Z23,Raw_data_N2_Kanji[[Receipe no]:[Receipe]],4,0),"") | F23: =IFERROR(VLOOKUP($B23&"_"&AA23,Raw_data_N2_Kanji[[Receipe no]:[Receipe]],4,0),"") | G23: =IFERROR(VLOOKUP($B23&"_"&AB23,Raw_data_N2_Kanji[[Receipe no]:[Receipe]],4,0),"") | H23: =IFERROR(VLOOKUP($B23&"_"&AC23,Raw_data_N2_Kanji[[Receipe no]:[Receipe]],4,0),"") | I23: =IFERROR(VLOOKUP($B23&"_"&AD23,Raw_data_N2_Kanji[[Receipe no]:[Receipe]],4,0),"") | J23: =IFERROR(VLOOKUP($B23&"_"&AE23,Raw_data_N2_Kanji[[Receipe no]:[Receipe]],4,0),"") | L23: =$W23 -> 2章1課 | M23: =IFERROR(VLOOKUP($L23&"_"&X23,Final_manabou_kanji[],6,0),"") | N23: =IFERROR(VLOOKUP($L23&"_"&Y23,Final_manabou_kanji[],6,0),"") | O23: =IFERROR(VLOOKUP($L23&"_"&Z23,Final_manabou_kanji[],6,0),"") | P23: =IFERROR(VLOOKUP($L23&"_"&AA23,Final_manabou_kanji[],6,0),"") | Q23: =IFERROR(VLOOKUP($L23&"_"&AB23,Final_manabou_kanji[],6,0),"") | R23: =IFERROR(VLOOKUP($L23&"_"&AC23,Final_manabou_kanji[],6,0),"") | S23: =IFERROR(VLOOKUP($L23&"_"&AD23,Final_manabou_kanji[],6,0),"") | T23: =IFERROR(VLOOKUP($L23&"_"&AE23,Final_manabou_kanji[],6,0),"") | W23: =IF(V23="",$W22,$V23) -> 2章1課 | X23: =IF($V23="",X22+8,X$1) -> 17 | Y23: =IF($V23="",Y22+8,Y$1) -> 18 | Z23: =IF($V23="",Z22+8,Z$1) -> 19 | AA23: =IF($V23="",AA22+8,AA$1) -> 20 | AB23: =IF($V23="",AB22+8,AB$1) -> 21 | AC23: =IF($V23="",AC22+8,AC$1) -> 22 | AD23: =IF($V23="",AD22+8,AD$1) -> 23 | AE23: =IF($V23="",AE22+8,AE$1) -> 24 | AH23: 24 | AI23: =$W23&X23 -> 2章1課17 | AJ23: =$W23&Y23 -> 2章1課18 | AK23: =$W23&Z23 -> 2章1課19 | AL23: =$W23&AA23 -> 2章1課20 | AM23: =$W23&AB23 -> 2章1課21 | AN23: =$W23&AC23 -> 2章1課22 | AO23: =$W23&AD23 -> 2章1課23 | AP23: =$W23&AE23 -> 2章1課24
A24: =IF($X24=1,$A23+1,$A23) -> 5 | B24: =IF(V24="",$B23,$V24) -> 2章1課 | C24: =IFERROR(VLOOKUP($B24&"_"&X24,Raw_data_N2_Kanji[[Receipe no]:[Receipe]],4,0),"") | D24: =IFERROR(VLOOKUP($B24&"_"&Y24,Raw_data_N2_Kanji[[Receipe no]:[Receipe]],4,0),"") | E24: =IFERROR(VLOOKUP($B24&"_"&Z24,Raw_data_N2_Kanji[[Receipe no]:[Receipe]],4,0),"") | F24: =IFERROR(VLOOKUP($B24&"_"&AA24,Raw_data_N2_Kanji[[Receipe no]:[Receipe]],4,0),"") | G24: =IFERROR(VLOOKUP($B24&"_"&AB24,Raw_data_N2_Kanji[[Receipe no]:[Receipe]],4,0),"") | H24: =IFERROR(VLOOKUP($B24&"_"&AC24,Raw_data_N2_Kanji[[Receipe no]:[Receipe]],4,0),"") | I24: =IFERROR(VLOOKUP($B24&"_"&AD24,Raw_data_N2_Kanji[[Receipe no]:[Receipe]],4,0),"") | J24: =IFERROR(VLOOKUP($B24&"_"&AE24,Raw_data_N2_Kanji[[Receipe no]:[Receipe]],4,0),"") | L24: =$W24 -> 2章1課 | M24: =IFERROR(VLOOKUP($L24&"_"&X24,Final_manabou_kanji[],6,0),"") | N24: =IFERROR(VLOOKUP($L24&"_"&Y24,Final_manabou_kanji[],6,0),"") | O24: =IFERROR(VLOOKUP($L24&"_"&Z24,Final_manabou_kanji[],6,0),"") | P24: =IFERROR(VLOOKUP($L24&"_"&AA24,Final_manabou_kanji[],6,0),"") | Q24: =IFERROR(VLOOKUP($L24&"_"&AB24,Final_manabou_kanji[],6,0),"") | R24: =IFERROR(VLOOKUP($L24&"_"&AC24,Final_manabou_kanji[],6,0),"") | S24: =IFERROR(VLOOKUP($L24&"_"&AD24,Final_manabou_kanji[],6,0),"") | T24: =IFERROR(VLOOKUP($L24&"_"&AE24,Final_manabou_kanji[],6,0),"") | W24: =IF(V24="",$W23,$V24) -> 2章1課 | X24: =IF($V24="",X23+8,X$1) -> 25 | Y24: =IF($V24="",Y23+8,Y$1) -> 26 | Z24: =IF($V24="",Z23+8,Z$1) -> 27 | AA24: =IF($V24="",AA23+8,AA$1) -> 28 | AB24: =IF($V24="",AB23+8,AB$1) -> 29 | AC24: =IF($V24="",AC23+8,AC$1) -> 30 | AD24: =IF($V24="",AD23+8,AD$1) -> 31 | AE24: =IF($V24="",AE23+8,AE$1) -> 32 | AH24: 24 | AI24: =$W24&X24 -> 2章1課25 | AJ24: =$W24&Y24 -> 2章1課26 | AK24: =$W24&Z24 -> 2章1課27 | AL24: =$W24&AA24 -> 2章1課28 | AM24: =$W24&AB24 -> 2章1課29 | AN24: =$W24&AC24 -> 2章1課30 | AO24: =$W24&AD24 -> 2章1課31 | AP24: =$W24&AE24 -> 2章1課32
A25: =IF($X25=1,$A24+1,$A24) -> 5 | B25: =IF(V25="",$B24,$V25) -> 2章1課 | C25: =IFERROR(VLOOKUP($B25&"_"&X25,Raw_data_N2_Kanji[[Receipe no]:[Receipe]],4,0),"") | D25: =IFERROR(VLOOKUP($B25&"_"&Y25,Raw_data_N2_Kanji[[Receipe no]:[Receipe]],4,0),"") | E25: =IFERROR(VLOOKUP($B25&"_"&Z25,Raw_data_N2_Kanji[[Receipe no]:[Receipe]],4,0),"") | F25: =IFERROR(VLOOKUP($B25&"_"&AA25,Raw_data_N2_Kanji[[Receipe no]:[Receipe]],4,0),"") | G25: =IFERROR(VLOOKUP($B25&"_"&AB25,Raw_data_N2_Kanji[[Receipe no]:[Receipe]],4,0),"") | H25: =IFERROR(VLOOKUP($B25&"_"&AC25,Raw_data_N2_Kanji[[Receipe no]:[Receipe]],4,0),"") | I25: =IFERROR(VLOOKUP($B25&"_"&AD25,Raw_data_N2_Kanji[[Receipe no]:[Receipe]],4,0),"") | J25: =IFERROR(VLOOKUP($B25&"_"&AE25,Raw_data_N2_Kanji[[Receipe no]:[Receipe]],4,0),"") | L25: =$W25 -> 2章1課 | M25: =IFERROR(VLOOKUP($L25&"_"&X25,Final_manabou_kanji[],6,0),"") | N25: =IFERROR(VLOOKUP($L25&"_"&Y25,Final_manabou_kanji[],6,0),"") | O25: =IFERROR(VLOOKUP($L25&"_"&Z25,Final_manabou_kanji[],6,0),"") | P25: =IFERROR(VLOOKUP($L25&"_"&AA25,Final_manabou_kanji[],6,0),"") | Q25: =IFERROR(VLOOKUP($L25&"_"&AB25,Final_manabou_kanji[],6,0),"") | R25: =IFERROR(VLOOKUP($L25&"_"&AC25,Final_manabou_kanji[],6,0),"") | S25: =IFERROR(VLOOKUP($L25&"_"&AD25,Final_manabou_kanji[],6,0),"") | T25: =IFERROR(VLOOKUP($L25&"_"&AE25,Final_manabou_kanji[],6,0),"") | W25: =IF(V25="",$W24,$V25) -> 2章1課 | X25: =IF($V25="",X24+8,X$1) -> 33 | Y25: =IF($V25="",Y24+8,Y$1) -> 34 | Z25: =IF($V25="",Z24+8,Z$1) -> 35 | AA25: =IF($V25="",AA24+8,AA$1) -> 36 | AB25: =IF($V25="",AB24+8,AB$1) -> 37 | AC25: =IF($V25="",AC24+8,AC$1) -> 38 | AD25: =IF($V25="",AD24+8,AD$1) -> 39 | AE25: =IF($V25="",AE24+8,AE$1) -> 40 | AH25: 24 | AI25: =$W25&X25 -> 2章1課33 | AJ25: =$W25&Y25 -> 2章1課34 | AK25: =$W25&Z25 -> 2章1課35 | AL25: =$W25&AA25 -> 2章1課36 | AM25: =$W25&AB25 -> 2章1課37 | AN25: =$W25&AC25 -> 2章1課38 | AO25: =$W25&AD25 -> 2章1課39 | AP25: =$W25&AE25 -> 2章1課40
A26: =IF($X26=1,$A25+1,$A25) -> 5 | B26: =IF(V26="",$B25,$V26) -> 2章1課 | C26: =IFERROR(VLOOKUP($B26&"_"&X26,Raw_data_N2_Kanji[[Receipe no]:[Receipe]],4,0),"") | D26: =IFERROR(VLOOKUP($B26&"_"&Y26,Raw_data_N2_Kanji[[Receipe no]:[Receipe]],4,0),"") | E26: =IFERROR(VLOOKUP($B26&"_"&Z26,Raw_data_N2_Kanji[[Receipe no]:[Receipe]],4,0),"") | F26: =IFERROR(VLOOKUP($B26&"_"&AA26,Raw_data_N2_Kanji[[Receipe no]:[Receipe]],4,0),"") | G26: =IFERROR(VLOOKUP($B26&"_"&AB26,Raw_data_N2_Kanji[[Receipe no]:[Receipe]],4,0),"") | H26: =IFERROR(VLOOKUP($B26&"_"&AC26,Raw_data_N2_Kanji[[Receipe no]:[Receipe]],4,0),"") | I26: =IFERROR(VLOOKUP($B26&"_"&AD26,Raw_data_N2_Kanji[[Receipe no]:[Receipe]],4,0),"") | J26: =IFERROR(VLOOKUP($B26&"_"&AE26,Raw_data_N2_Kanji[[Receipe no]:[Receipe]],4,0),"") | L26: =$W26 -> 2章1課 | M26: =IFERROR(VLOOKUP($L26&"_"&X26,Final_manabou_kanji[],6,0),"") | N26: =IFERROR(VLOOKUP($L26&"_"&Y26,Final_manabou_kanji[],6,0),"") | O26: =IFERROR(VLOOKUP($L26&"_"&Z26,Final_manabou_kanji[],6,0),"") | P26: =IFERROR(VLOOKUP($L26&"_"&AA26,Final_manabou_kanji[],6,0),"") | Q26: =IFERROR(VLOOKUP($L26&"_"&AB26,Final_manabou_kanji[],6,0),"") | R26: =IFERROR(VLOOKUP($L26&"_"&AC26,Final_manabou_kanji[],6,0),"") | S26: =IFERROR(VLOOKUP($L26&"_"&AD26,Final_manabou_kanji[],6,0),"") | T26: =IFERROR(VLOOKUP($L26&"_"&AE26,Final_manabou_kanji[],6,0),"") | W26: =IF(V26="",$W25,$V26) -> 2章1課 | X26: =IF($V26="",X25+8,X$1) -> 41 | Y26: =IF($V26="",Y25+8,Y$1) -> 42 | Z26: =IF($V26="",Z25+8,Z$1) -> 43 | AA26: =IF($V26="",AA25+8,AA$1) -> 44 | AB26: =IF($V26="",AB25+8,AB$1) -> 45 | AC26: =IF($V26="",AC25+8,AC$1) -> 46 | AD26: =IF($V26="",AD25+8,AD$1) -> 47 | AE26: =IF($V26="",AE25+8,AE$1) -> 48 | AH26: 24 | AI26: =$W26&X26 -> 2章1課41 | AJ26: =$W26&Y26 -> 2章1課42 | AK26: =$W26&Z26 -> 2章1課43 | AL26: =$W26&AA26 -> 2章1課44 | AM26: =$W26&AB26 -> 2章1課45 | AN26: =$W26&AC26 -> 2章1課46 | AO26: =$W26&AD26 -> 2章1課47 | AP26: =$W26&AE26 -> 2章1課48
A27: =IF($X27=1,$A26+1,$A26) -> 6 | B27: =IF(V27="",$B26,$V27) -> 2章2課 | C27: =IFERROR(VLOOKUP($B27&"_"&X27,Raw_data_N2_Kanji[[Receipe no]:[Receipe]],4,0),"") | D27: =IFERROR(VLOOKUP($B27&"_"&Y27,Raw_data_N2_Kanji[[Receipe no]:[Receipe]],4,0),"") | E27: =IFERROR(VLOOKUP($B27&"_"&Z27,Raw_data_N2_Kanji[[Receipe no]:[Receipe]],4,0),"") | F27: =IFERROR(VLOOKUP($B27&"_"&AA27,Raw_data_N2_Kanji[[Receipe no]:[Receipe]],4,0),"") | G27: =IFERROR(VLOOKUP($B27&"_"&AB27,Raw_data_N2_Kanji[[Receipe no]:[Receipe]],4,0),"") | H27: =IFERROR(VLOOKUP($B27&"_"&AC27,Raw_data_N2_Kanji[[Receipe no]:[Receipe]],4,0),"") | I27: =IFERROR(VLOOKUP($B27&"_"&AD27,Raw_data_N2_Kanji[[Receipe no]:[Receipe]],4,0),"") | J27: =IFERROR(VLOOKUP($B27&"_"&AE27,Raw_data_N2_Kanji[[Receipe no]:[Receipe]],4,0),"") | L27: =$W27 -> 2章2課 | M27: =IFERROR(VLOOKUP($L27&"_"&X27,Final_manabou_kanji[],6,0),"") | N27: =IFERROR(VLOOKUP($L27&"_"&Y27,Final_manabou_kanji[],6,0),"") | O27: =IFERROR(VLOOKUP($L27&"_"&Z27,Final_manabou_kanji[],6,0),"") | P27: =IFERROR(VLOOKUP($L27&"_"&AA27,Final_manabou_kanji[],6,0),"") | Q27: =IFERROR(VLOOKUP($L27&"_"&AB27,Final_manabou_kanji[],6,0),"") | R27: =IFERROR(VLOOKUP($L27&"_"&AC27,Final_manabou_kanji[],6,0),"") | S27: =IFERROR(VLOOKUP($L27&"_"&AD27,Final_manabou_kanji[],6,0),"") | T27: =IFERROR(VLOOKUP($L27&"_"&AE27,Final_manabou_kanji[],6,0),"") | V27: 2章2課 | W27: =IF(V27="",$W26,$V27) -> 2章2課 | X27: =IF($V27="",X26+8,X$1) -> 1 | Y27: =IF($V27="",Y26+8,Y$1) -> 2 | Z27: =IF($V27="",Z26+8,Z$1) -> 3 | AA27: =IF($V27="",AA26+8,AA$1) -> 4 | AB27: =IF($V27="",AB26+8,AB$1) -> 5 | AC27: =IF($V27="",AC26+8,AC$1) -> 6 | AD27: =IF($V27="",AD26+8,AD$1) -> 7 | AE27: =IF($V27="",AE26+8,AE$1) -> 8 | AH27: 24 | AI27: =$W27&X27 -> 2章2課1 | AJ27: =$W27&Y27 -> 2章2課2 | AK27: =$W27&Z27 -> 2章2課3 | AL27: =$W27&AA27 -> 2章2課4 | AM27: =$W27&AB27 -> 2章2課5 | AN27: =$W27&AC27 -> 2章2課6 | AO27: =$W27&AD27 -> 2章2課7 | AP27: =$W27&AE27 -> 2章2課8
A28: =IF($X28=1,$A27+1,$A27) -> 6 | B28: =IF(V28="",$B27,$V28) -> 2章2課 | C28: =IFERROR(VLOOKUP($B28&"_"&X28,Raw_data_N2_Kanji[[Receipe no]:[Receipe]],4,0),"") | D28: =IFERROR(VLOOKUP($B28&"_"&Y28,Raw_data_N2_Kanji[[Receipe no]:[Receipe]],4,0),"") | E28: =IFERROR(VLOOKUP($B28&"_"&Z28,Raw_data_N2_Kanji[[Receipe no]:[Receipe]],4,0),"") | F28: =IFERROR(VLOOKUP($B28&"_"&AA28,Raw_data_N2_Kanji[[Receipe no]:[Receipe]],4,0),"") | G28: =IFERROR(VLOOKUP($B28&"_"&AB28,Raw_data_N2_Kanji[[Receipe no]:[Receipe]],4,0),"") | H28: =IFERROR(VLOOKUP($B28&"_"&AC28,Raw_data_N2_Kanji[[Receipe no]:[Receipe]],4,0),"") | I28: =IFERROR(VLOOKUP($B28&"_"&AD28,Raw_data_N2_Kanji[[Receipe no]:[Receipe]],4,0),"") | J28: =IFERROR(VLOOKUP($B28&"_"&AE28,Raw_data_N2_Kanji[[Receipe no]:[Receipe]],4,0),"") | L28: =$W28 -> 2章2課 | M28: =IFERROR(VLOOKUP($L28&"_"&X28,Final_manabou_kanji[],6,0),"") | N28: =IFERROR(VLOOKUP($L28&"_"&Y28,Final_manabou_kanji[],6,0),"") | O28: =IFERROR(VLOOKUP($L28&"_"&Z28,Final_manabou_kanji[],6,0),"") | P28: =IFERROR(VLOOKUP($L28&"_"&AA28,Final_manabou_kanji[],6,0),"") | Q28: =IFERROR(VLOOKUP($L28&"_"&AB28,Final_manabou_kanji[],6,0),"") | R28: =IFERROR(VLOOKUP($L28&"_"&AC28,Final_manabou_kanji[],6,0),"") | S28: =IFERROR(VLOOKUP($L28&"_"&AD28,Final_manabou_kanji[],6,0),"") | T28: =IFERROR(VLOOKUP($L28&"_"&AE28,Final_manabou_kanji[],6,0),"") | W28: =IF(V28="",$W27,$V28) -> 2章2課 | X28: =IF($V28="",X27+8,X$1) -> 9 | Y28: =IF($V28="",Y27+8,Y$1) -> 10 | Z28: =IF($V28="",Z27+8,Z$1) -> 11 | AA28: =IF($V28="",AA27+8,AA$1) -> 12 | AB28: =IF($V28="",AB27+8,AB$1) -> 13 | AC28: =IF($V28="",AC27+8,AC$1) -> 14 | AD28: =IF($V28="",AD27+8,AD$1) -> 15 | AE28: =IF($V28="",AE27+8,AE$1) -> 16 | AH28: 24 | AI28: =$W28&X28 -> 2章2課9 | AJ28: =$W28&Y28 -> 2章2課10 | AK28: =$W28&Z28 -> 2章2課11 | AL28: =$W28&AA28 -> 2章2課12 | AM28: =$W28&AB28 -> 2章2課13 | AN28: =$W28&AC28 -> 2章2課14 | AO28: =$W28&AD28 -> 2章2課15 | AP28: =$W28&AE28 -> 2章2課16
